Workbook

Sheet Locations
A1: Station Name | B1: OBS | D1: Date/Time (UTC) | J1: Planned Location | M1: Actual Launch Location | Q1: Surveyed Location (Seafloor) | X1: First Surfacing Location | AB1: Recovery Location | AF1: Planned vs. Seafloor | AH1: Days Recording | AI1: Days at Seafloor | AJ1: Clock Drift | AL1: Actual Sample Rate (250Hz) | AM1: Tilt Estimate | AO1: Elapsed Time (min) | AT1: Movement Rate (m/min)
B2: Name | C2: Serial | D2: Launch | E2: On Seafloor | F2: Survey Start | G2: Released | H2: Surfaced | I2: Recovered | J2: Latitude | K2: Longitude | L2: Depth (m) | M2: Latitude | N2: Longitude | O2: Depth (m) | P2: Distance from Planned (km) | Q2: Latitude | R2: Longitude | S2: Depth (m) | T2: Std Error (m) | U2: Horizontal Drift (m) | V2: Drift (% Depth) | W2: Bearing from Drop | X2: Latitude | Y2: Longitude | Z2: Horizontal Drift (m) | AA2: Bearing from Survey | AB2: Latitude | AC2: Longitude | AD2: Distance from Surfacing (km) | AF2: Distance (m) | AG2: Bearing | AJ2: ms/day | AK2: ppm | AM2: Deploy | AN2: Recover | AO2: Sink | AP2: Rise | AQ2: Burn | AR2: Floating | AS2: On Station (Recovery) | AT2: Sink | AU2: Rise
A3: Station | B3: OBS Name | C3: OBS ID | D3: Launch Date/Time (UTC) | E3: Date/Time on Seafloor (UTC) | F3: Survey Start Date/Time (UTC) | G3: Date/Time Released (UTC) | H3: Surfaced Date/Time (UTC) | I3: Recovery Date/Time (UTC) | J3: Planned Latitude | K3: Planned Longitude | L3: Planned Depth (m) | M3: Launch Latitude | N3: Launch Longitude | O3: Water Depth at Launch (m) | P3: Distance Launch from Planned (km) | Q3: Surveyed Latitude | R3: Surveyed Longitude | S3: Surveyed Depth (m) | T3: Survey Std Error (m) | U3: Horizontal Drift during Fall (m) | V3: Horizontal Fall Drift (% Depth) | W3: Bearing Surveyed from Launch | X3: Surfacing Latitude | Y3: Surfacing Longitude | Z3: Horizontal Drift during Rise (m) | AA3: Bearing Surfacing from Surveyed | AB3: Recovery Latitude | AC3: Recovery Longitude | AD3: Drift on Surface (km)
A4: ='Deployment Log'!A4 -> 0 | B4: ='Deployment Log'!S4 -> 0 | C4: ='Deployment Log'!T4 -> 0 | D4: =IF('Deployment Log'!N4>DATE(2021,8,1),'Deployment Log'!N4,"n/a") -> n/a | E4: =IF('Deployment Log'!O4>DATE(2021,8,1),'Deployment Log'!O4,"n/a") -> n/a | F4: =IF('Deployment Log'!P4>DATE(2021,8,1),'Deployment Log'!P4,"n/a") -> n/a | G4: =IF('Recovery Log'!L4>DATE(2021,8,1),'Recovery Log'!L4,"n/a") -> n/a | H4: =IF('Recovery Log'!M4>DATE(2021,8,1),'Recovery Log'!M4,"n/a") -> n/a | I4: =IF(MIN('Recovery Log'!N4:O4)>DATE(2021,8,1),MIN('Recovery Log'!N4:O4),"n/a") -> n/a | J4: ='Deployment Log'!B4 -> 0 | K4: ='Deployment Log'!C4 -> 0 | L4: ='Deployment Log'!D4 -> 0 | M4: ='Deployment Log'!I4 -> 0 | N4: ='Deployment Log'!J4 -> 0 | O4: ='Deployment Log'!K4 -> 0 | P4: ='Deployment Log'!L4 | U4: =IF(ISBLANK(Q4),"",2*6370*ASIN(SQRT(SIN(RADIANS(Q4-M4)/2)*SIN(RADIANS(Q4-M4)/2) + COS(RADIANS(Q4))*COS(RADIANS(M4))*SIN(RADIANS(R4-N4)/2)*SIN(RADIANS(R4-N4)/2)))*1000) | V4: =ABS(U4/S4) -> #VALUE! | W4: =IF(ISBLANK(Q4),"",MOD(DEGREES(ATAN2(COS(RADIANS(M4))*SIN(RADIANS(Q4)) - SIN(RADIANS(M4))*COS(RADIANS(Q4))*COS(RADIANS(R4-N4)),COS(RADIANS(Q4))*SIN(RADIANS(R4-N4)))) + 360, 360)) | X4: =IF('Recovery Log'!V4="","",'Recovery Log'!V4) | Y4: =IF('Recovery Log'!W4="","",'Recovery Log'!W4) | Z4: ='Recovery Log'!X4 | AA4: =IF(ISBLANK(Q4),"",MOD(DEGREES(ATAN2(COS(RADIANS(Q4))*SIN(RADIANS(X4)) - SIN(RADIANS(Q4))*COS(RADIANS(X4))*COS(RADIANS(Y4-R4)),COS(RADIANS(X4))*SIN(RADIANS(Y4-R4)))) + 360, 360)) | AB4: =IF('Recovery Log'!Y4="","",'Recovery Log'!Y4) | AC4: =IF('Recovery Log'!Z4="","",'Recovery Log'!Z4) | AD4: ='Recovery Log'!AA4 | AF4: =IF(ISBLANK(Q4),"",2*6370*ASIN(SQRT(SIN(RADIANS(Q4-J4)/2)*SIN(RADIANS(Q4-J4)/2) + COS(RADIANS(Q4))*COS(RADIANS(J4))*SIN(RADIANS(R4-K4)/2)*SIN(RADIANS(R4-K4)/2)))*1000) | AG4: =IF(ISBLANK(Q4),"",MOD(DEGREES(ATAN2(COS(RADIANS(J4))*SIN(RADIANS(Q4)) - SIN(RADIANS(J4))*COS(RADIANS(Q4))*COS(RADIANS(R4-K4)),COS(RADIANS(Q4))*SIN(RADIANS(R4-K4)))) + 360, 360)) | AH4: =IF('Recovery Log'!O4>'Deployment Log'!M4,'Recovery Log'!O4-'Deployment Log'!M4,"n/a") -> n/a | AI4: =IF(AND(ISNUMBER(G4),ISNUMBER(E4)),G4-E4,"n/a") -> n/a | AJ4: =IF(ISNUMBER(AH4),'Recovery Log'!AC4/AH4,"n/a") -> n/a | AK4: =IF(ISNUMBER(AJ4),1000000*AJ4/(24*60*60*1000),"n/a") -> n/a | AL4: =IF(ISNUMBER(AJ4),250+AJ4/24/60/60/250,"n/a") -> n/a | AM4: =IF(ISBLANK('Deployment Log'!AF4),"n/a",DEGREES(ATAN2('Deployment Log'!AF4,SQRT('Deployment Log'!AG4^2 + 'Deployment Log'!AH4^2)))) -> n/a | AN4: =IF(ISBLANK('Recovery Log'!P4),"n/a",DEGREES(ATAN2('Recovery Log'!P4,SQRT('Recovery Log'!Q4^2 + 'Recovery Log'!R4^2)))) -> n/a | AO4: =IF(AND(ISNUMBER(D4),ISNUMBER(E4)),(E4-D4)*24*60,"n/a") -> n/a | AP4: =IF(AND(ISNUMBER(G4),ISNUMBER(H4)),(H4-G4)*24*60,"n/a") -> n/a | AQ4: =IF(AND(ISNUMBER(G4),ISNUMBER('Recovery Log'!K4)),(G4-'Recovery Log'!K4)*24*60,"n/a") -> n/a | AR4: =IF(AND(ISNUMBER(H4),ISNUMBER(I4)),(I4-H4)*24*60,"n/a") -> n/a | AS4: =IF(AND(ISNUMBER('Recovery Log'!I4),ISNUMBER('Recovery Log'!N4)),('Recovery Log'!N4-'Recovery Log'!I4)*24*60,"n/a") -> n/a | AT4: =IF(ISNUMBER(AO4),O4/AO4,"n/a") -> n/a | AU4: =IF(ISNUMBER(AP4),O4/AP4,"n/a") -> n/a
A5: ='Deployment Log'!A5 -> 0 | B5: ='Deployment Log'!S5 -> 0 | C5: ='Deployment Log'!T5 -> 0 | D5: =IF('Deployment Log'!N5>DATE(2021,8,1),'Deployment Log'!N5,"n/a") -> n/a | E5: =IF('Deployment Log'!O5>DATE(2021,8,1),'Deployment Log'!O5,"n/a") -> n/a | F5: =IF('Deployment Log'!P5>DATE(2021,8,1),'Deployment Log'!P5,"n/a") -> n/a | G5: =IF('Recovery Log'!L5>DATE(2021,8,1),'Recovery Log'!L5,"n/a") -> n/a | H5: =IF('Recovery Log'!M5>DATE(2021,8,1),'Recovery Log'!M5,"n/a") -> n/a | I5: =IF(MIN('Recovery Log'!N5:O5)>DATE(2021,8,1),MIN('Recovery Log'!N5:O5),"n/a") -> n/a | J5: ='Deployment Log'!B5 -> 0 | K5: ='Deployment Log'!C5 -> 0 | L5: ='Deployment Log'!D5 -> 0 | M5: ='Deployment Log'!I5 -> 0 | N5: ='Deployment Log'!J5 -> 0 | O5: ='Deployment Log'!K5 -> 0 | P5: ='Deployment Log'!L5 | U5: =IF(ISBLANK(Q5),"",2*6370*ASIN(SQRT(SIN(RADIANS(Q5-M5)/2)*SIN(RADIANS(Q5-M5)/2) + COS(RADIANS(Q5))*COS(RADIANS(M5))*SIN(RADIANS(R5-N5)/2)*SIN(RADIANS(R5-N5)/2)))*1000) | V5: =ABS(U5/S5) -> #VALUE! | W5: =IF(ISBLANK(Q5),"",MOD(DEGREES(ATAN2(COS(RADIANS(M5))*SIN(RADIANS(Q5)) - SIN(RADIANS(M5))*COS(RADIANS(Q5))*COS(RADIANS(R5-N5)),COS(RADIANS(Q5))*SIN(RADIANS(R5-N5)))) + 360, 360)) | X5: =IF('Recovery Log'!V5="","",'Recovery Log'!V5) | Y5: =IF('Recovery Log'!W5="","",'Recovery Log'!W5) | Z5: ='Recovery Log'!X5 | AA5: =IF(ISBLANK(Q5),"",MOD(DEGREES(ATAN2(COS(RADIANS(Q5))*SIN(RADIANS(X5)) - SIN(RADIANS(Q5))*COS(RADIANS(X5))*COS(RADIANS(Y5-R5)),COS(RADIANS(X5))*SIN(RADIANS(Y5-R5)))) + 360, 360)) | AB5: =IF('Recovery Log'!Y5="","",'Recovery Log'!Y5) | AC5: =IF('Recovery Log'!Z5="","",'Recovery Log'!Z5) | AD5: ='Recovery Log'!AA5 | AF5: =IF(ISBLANK(Q5),"",2*6370*ASIN(SQRT(SIN(RADIANS(Q5-J5)/2)*SIN(RADIANS(Q5-J5)/2) + COS(RADIANS(Q5))*COS(RADIANS(J5))*SIN(RADIANS(R5-K5)/2)*SIN(RADIANS(R5-K5)/2)))*1000) | AG5: =IF(ISBLANK(Q5),"",MOD(DEGREES(ATAN2(COS(RADIANS(J5))*SIN(RADIANS(Q5)) - SIN(RADIANS(J5))*COS(RADIANS(Q5))*COS(RADIANS(R5-K5)),COS(RADIANS(Q5))*SIN(RADIANS(R5-K5)))) + 360, 360)) | AH5: =IF('Recovery Log'!O5>'Deployment Log'!M5,'Recovery Log'!O5-'Deployment Log'!M5,"n/a") -> n/a | AI5: =IF(AND(ISNUMBER(G5),ISNUMBER(E5)),G5-E5,"n/a") -> n/a | AJ5: =IF(ISNUMBER(AH5),'Recovery Log'!AC5/AH5,"n/a") -> n/a | AK5: =IF(ISNUMBER(AJ5),1000000*AJ5/(24*60*60*1000),"n/a") -> n/a | AL5: =IF(ISNUMBER(AJ5),250+AJ5/24/60/60/250,"n/a") -> n/a | AM5: =IF(ISBLANK('Deployment Log'!AF5),"n/a",DEGREES(ATAN2('Deployment Log'!AF5,SQRT('Deployment Log'!AG5^2 + 'Deployment Log'!AH5^2)))) -> n/a | AN5: =IF(ISBLANK('Recovery Log'!P5),"n/a",DEGREES(ATAN2('Recovery Log'!P5,SQRT('Recovery Log'!Q5^2 + 'Recovery Log'!R5^2)))) -> n/a | AO5: =IF(AND(ISNUMBER(D5),ISNUMBER(E5)),(E5-D5)*24*60,"n/a") -> n/a | AP5: =IF(AND(ISNUMBER(G5),ISNUMBER(H5)),(H5-G5)*24*60,"n/a") -> n/a | AQ5: =IF(AND(ISNUMBER(G5),ISNUMBER('Recovery Log'!K5)),(G5-'Recovery Log'!K5)*24*60,"n/a") -> n/a | AR5: =IF(AND(ISNUMBER(H5),ISNUMBER(I5)),(I5-H5)*24*60,"n/a") -> n/a | AS5: =IF(AND(ISNUMBER('Recovery Log'!I5),ISNUMBER('Recovery Log'!N5)),('Recovery Log'!N5-'Recovery Log'!I5)*24*60,"n/a") -> n/a | AT5: =IF(ISNUMBER(AO5),O5/AO5,"n/a") -> n/a | AU5: =IF(ISNUMBER(AP5),O5/AP5,"n/a") -> n/a
A6: ='Deployment Log'!A6 -> 0 | B6: ='Deployment Log'!S6 -> 0 | C6: ='Deployment Log'!T6 -> 0 | D6: =IF('Deployment Log'!N6>DATE(2021,8,1),'Deployment Log'!N6,"n/a") -> n/a | E6: =IF('Deployment Log'!O6>DATE(2021,8,1),'Deployment Log'!O6,"n/a") -> n/a | F6: =IF('Deployment Log'!P6>DATE(2021,8,1),'Deployment Log'!P6,"n/a") -> n/a | G6: =IF('Recovery Log'!L6>DATE(2021,8,1),'Recovery Log'!L6,"n/a") -> n/a | H6: =IF('Recovery Log'!M6>DATE(2021,8,1),'Recovery Log'!M6,"n/a") -> n/a | I6: =IF(MIN('Recovery Log'!N6:O6)>DATE(2021,8,1),MIN('Recovery Log'!N6:O6),"n/a") -> n/a | J6: ='Deployment Log'!B6 -> 0 | K6: ='Deployment Log'!C6 -> 0 | L6: ='Deployment Log'!D6 -> 0 | M6: ='Deployment Log'!I6 -> 0 | N6: ='Deployment Log'!J6 -> 0 | O6: ='Deployment Log'!K6 -> 0 | P6: ='Deployment Log'!L6 | U6: =IF(ISBLANK(Q6),"",2*6370*ASIN(SQRT(SIN(RADIANS(Q6-M6)/2)*SIN(RADIANS(Q6-M6)/2) + COS(RADIANS(Q6))*COS(RADIANS(M6))*SIN(RADIANS(R6-N6)/2)*SIN(RADIANS(R6-N6)/2)))*1000) | V6: =ABS(U6/S6) -> #VALUE! | W6: =IF(ISBLANK(Q6),"",MOD(DEGREES(ATAN2(COS(RADIANS(M6))*SIN(RADIANS(Q6)) - SIN(RADIANS(M6))*COS(RADIANS(Q6))*COS(RADIANS(R6-N6)),COS(RADIANS(Q6))*SIN(RADIANS(R6-N6)))) + 360, 360)) | X6: =IF('Recovery Log'!V6="","",'Recovery Log'!V6) | Y6: =IF('Recovery Log'!W6="","",'Recovery Log'!W6) | Z6: ='Recovery Log'!X6 | AA6: =IF(ISBLANK(Q6),"",MOD(DEGREES(ATAN2(COS(RADIANS(Q6))*SIN(RADIANS(X6)) - SIN(RADIANS(Q6))*COS(RADIANS(X6))*COS(RADIANS(Y6-R6)),COS(RADIANS(X6))*SIN(RADIANS(Y6-R6)))) + 360, 360)) | AB6: =IF('Recovery Log'!Y6="","",'Recovery Log'!Y6) | AC6: =IF('Recovery Log'!Z6="","",'Recovery Log'!Z6) | AD6: ='Recovery Log'!AA6 | AF6: =IF(ISBLANK(Q6),"",2*6370*ASIN(SQRT(SIN(RADIANS(Q6-J6)/2)*SIN(RADIANS(Q6-J6)/2) + COS(RADIANS(Q6))*COS(RADIANS(J6))*SIN(RADIANS(R6-K6)/2)*SIN(RADIANS(R6-K6)/2)))*1000) | AG6: =IF(ISBLANK(Q6),"",MOD(DEGREES(ATAN2(COS(RADIANS(J6))*SIN(RADIANS(Q6)) - SIN(RADIANS(J6))*COS(RADIANS(Q6))*COS(RADIANS(R6-K6)),COS(RADIANS(Q6))*SIN(RADIANS(R6-K6)))) + 360, 360)) | AH6: =IF('Recovery Log'!O6>'Deployment Log'!M6,'Recovery Log'!O6-'Deployment Log'!M6,"n/a") -> n/a | AI6: =IF(AND(ISNUMBER(G6),ISNUMBER(E6)),G6-E6,"n/a") -> n/a | AJ6: =IF(ISNUMBER(AH6),'Recovery Log'!AC6/AH6,"n/a") -> n/a | AK6: =IF(ISNUMBER(AJ6),1000000*AJ6/(24*60*60*1000),"n/a") -> n/a | AL6: =IF(ISNUMBER(AJ6),250+AJ6/24/60/60/250,"n/a") -> n/a | AM6: =IF(ISBLANK('Deployment Log'!AF6),"n/a",DEGREES(ATAN2('Deployment Log'!AF6,SQRT('Deployment Log'!AG6^2 + 'Deployment Log'!AH6^2)))) -> n/a | AN6: =IF(ISBLANK('Recovery Log'!P6),"n/a",DEGREES(ATAN2('Recovery Log'!P6,SQRT('Recovery Log'!Q6^2 + 'Recovery Log'!R6^2)))) -> n/a | AO6: =IF(AND(ISNUMBER(D6),ISNUMBER(E6)),(E6-D6)*24*60,"n/a") -> n/a | AP6: =IF(AND(ISNUMBER(G6),ISNUMBER(H6)),(H6-G6)*24*60,"n/a") -> n/a | AQ6: =IF(AND(ISNUMBER(G6),ISNUMBER('Recovery Log'!K6)),(G6-'Recovery Log'!K6)*24*60,"n/a") -> n/a | AR6: =IF(AND(ISNUMBER(H6),ISNUMBER(I6)),(I6-H6)*24*60,"n/a") -> n/a | AS6: =IF(AND(ISNUMBER('Recovery Log'!I6),ISNUMBER('Recovery Log'!N6)),('Recovery Log'!N6-'Recovery Log'!I6)*24*60,"n/a") -> n/a | AT6: =IF(ISNUMBER(AO6),O6/AO6,"n/a") -> n/a | AU6: =IF(ISNUMBER(AP6),O6/AP6,"n/a") -> n/a
A7: ='Deployment Log'!A7 -> 0 | B7: ='Deployment Log'!S7 -> 0 | C7: ='Deployment Log'!T7 -> 0 | D7: =IF('Deployment Log'!N7>DATE(2021,8,1),'Deployment Log'!N7,"n/a") -> n/a | E7: =IF('Deployment Log'!O7>DATE(2021,8,1),'Deployment Log'!O7,"n/a") -> n/a | F7: =IF('Deployment Log'!P7>DATE(2021,8,1),'Deployment Log'!P7,"n/a") -> n/a | G7: =IF('Recovery Log'!L7>DATE(2021,8,1),'Recovery Log'!L7,"n/a") -> n/a | H7: =IF('Recovery Log'!M7>DATE(2021,8,1),'Recovery Log'!M7,"n/a") -> n/a | I7: =IF(MIN('Recovery Log'!N7:O7)>DATE(2021,8,1),MIN('Recovery Log'!N7:O7),"n/a") -> n/a | J7: ='Deployment Log'!B7 -> 0 | K7: ='Deployment Log'!C7 -> 0 | L7: ='Deployment Log'!D7 -> 0 | M7: ='Deployment Log'!I7 -> 0 | N7: ='Deployment Log'!J7 -> 0 | O7: ='Deployment Log'!K7 -> 0 | P7: ='Deployment Log'!L7 | U7: =IF(ISBLANK(Q7),"",2*6370*ASIN(SQRT(SIN(RADIANS(Q7-M7)/2)*SIN(RADIANS(Q7-M7)/2) + COS(RADIANS(Q7))*COS(RADIANS(M7))*SIN(RADIANS(R7-N7)/2)*SIN(RADIANS(R7-N7)/2)))*1000) | V7: =ABS(U7/S7) -> #VALUE! | W7: =IF(ISBLANK(Q7),"",MOD(DEGREES(ATAN2(COS(RADIANS(M7))*SIN(RADIANS(Q7)) - SIN(RADIANS(M7))*COS(RADIANS(Q7))*COS(RADIANS(R7-N7)),COS(RADIANS(Q7))*SIN(RADIANS(R7-N7)))) + 360, 360)) | X7: =IF('Recovery Log'!V7="","",'Recovery Log'!V7) | Y7: =IF('Recovery Log'!W7="","",'Recovery Log'!W7) | Z7: ='Recovery Log'!X7 | AA7: =IF(ISBLANK(Q7),"",MOD(DEGREES(ATAN2(COS(RADIANS(Q7))*SIN(RADIANS(X7)) - SIN(RADIANS(Q7))*COS(RADIANS(X7))*COS(RADIANS(Y7-R7)),COS(RADIANS(X7))*SIN(RADIANS(Y7-R7)))) + 360, 360)) | AB7: =IF('Recovery Log'!Y7="","",'Recovery Log'!Y7) | AC7: =IF('Recovery Log'!Z7="","",'Recovery Log'!Z7) | AD7: ='Recovery Log'!AA7 | AF7: =IF(ISBLANK(Q7),"",2*6370*ASIN(SQRT(SIN(RADIANS(Q7-J7)/2)*SIN(RADIANS(Q7-J7)/2) + COS(RADIANS(Q7))*COS(RADIANS(J7))*SIN(RADIANS(R7-K7)/2)*SIN(RADIANS(R7-K7)/2)))*1000) | AG7: =IF(ISBLANK(Q7),"",MOD(DEGREES(ATAN2(COS(RADIANS(J7))*SIN(RADIANS(Q7)) - SIN(RADIANS(J7))*COS(RADIANS(Q7))*COS(RADIANS(R7-K7)),COS(RADIANS(Q7))*SIN(RADIANS(R7-K7)))) + 360, 360)) | AH7: =IF('Recovery Log'!O7>'Deployment Log'!M7,'Recovery Log'!O7-'Deployment Log'!M7,"n/a") -> n/a | AI7: =IF(AND(ISNUMBER(G7),ISNUMBER(E7)),G7-E7,"n/a") -> n/a | AJ7: =IF(ISNUMBER(AH7),'Recovery Log'!AC7/AH7,"n/a") -> n/a | AK7: =IF(ISNUMBER(AJ7),1000000*AJ7/(24*60*60*1000),"n/a") -> n/a | AL7: =IF(ISNUMBER(AJ7),250+AJ7/24/60/60/250,"n/a") -> n/a | AM7: =IF(ISBLANK('Deployment Log'!AF7),"n/a",DEGREES(ATAN2('Deployment Log'!AF7,SQRT('Deployment Log'!AG7^2 + 'Deployment Log'!AH7^2)))) -> n/a | AN7: =IF(ISBLANK('Recovery Log'!P7),"n/a",DEGREES(ATAN2('Recovery Log'!P7,SQRT('Recovery Log'!Q7^2 + 'Recovery Log'!R7^2)))) -> n/a | AO7: =IF(AND(ISNUMBER(D7),ISNUMBER(E7)),(E7-D7)*24*60,"n/a") -> n/a | AP7: =IF(AND(ISNUMBER(G7),ISNUMBER(H7)),(H7-G7)*24*60,"n/a") -> n/a | AQ7: =IF(AND(ISNUMBER(G7),ISNUMBER('Recovery Log'!K7)),(G7-'Recovery Log'!K7)*24*60,"n/a") -> n/a | AR7: =IF(AND(ISNUMBER(H7),ISNUMBER(I7)),(I7-H7)*24*60,"n/a") -> n/a | AS7: =IF(AND(ISNUMBER('Recovery Log'!I7),ISNUMBER('Recovery Log'!N7)),('Recovery Log'!N7-'Recovery Log'!I7)*24*60,"n/a") -> n/a | AT7: =IF(ISNUMBER(AO7),O7/AO7,"n/a") -> n/a | AU7: =IF(ISNUMBER(AP7),O7/AP7,"n/a") -> n/a
A8: ='Deployment Log'!A8 -> 0 | B8: ='Deployment Log'!S8 -> 0 | C8: ='Deployment Log'!T8 -> 0 | D8: =IF('Deployment Log'!N8>DATE(2021,8,1),'Deployment Log'!N8,"n/a") -> n/a | E8: =IF('Deployment Log'!O8>DATE(2021,8,1),'Deployment Log'!O8,"n/a") -> n/a | F8: =IF('Deployment Log'!P8>DATE(2021,8,1),'Deployment Log'!P8,"n/a") -> n/a | G8: =IF('Recovery Log'!L8>DATE(2021,8,1),'Recovery Log'!L8,"n/a") -> n/a | H8: =IF('Recovery Log'!M8>DATE(2021,8,1),'Recovery Log'!M8,"n/a") -> n/a | I8: =IF(MIN('Recovery Log'!N8:O8)>DATE(2021,8,1),MIN('Recovery Log'!N8:O8),"n/a") -> n/a | J8: ='Deployment Log'!B8 -> 0 | K8: ='Deployment Log'!C8 -> 0 | L8: ='Deployment Log'!D8 -> 0 | M8: ='Deployment Log'!I8 -> 0 | N8: ='Deployment Log'!J8 -> 0 | O8: ='Deployment Log'!K8 -> 0 | P8: ='Deployment Log'!L8 | U8: =IF(ISBLANK(Q8),"",2*6370*ASIN(SQRT(SIN(RADIANS(Q8-M8)/2)*SIN(RADIANS(Q8-M8)/2) + COS(RADIANS(Q8))*COS(RADIANS(M8))*SIN(RADIANS(R8-N8)/2)*SIN(RADIANS(R8-N8)/2)))*1000) | V8: =ABS(U8/S8) -> #VALUE! | W8: =IF(ISBLANK(Q8),"",MOD(DEGREES(ATAN2(COS(RADIANS(M8))*SIN(RADIANS(Q8)) - SIN(RADIANS(M8))*COS(RADIANS(Q8))*COS(RADIANS(R8-N8)),COS(RADIANS(Q8))*SIN(RADIANS(R8-N8)))) + 360, 360)) | X8: =IF('Recovery Log'!V8="","",'Recovery Log'!V8) | Y8: =IF('Recovery Log'!W8="","",'Recovery Log'!W8) | Z8: ='Recovery Log'!X8 | AA8: =IF(ISBLANK(Q8),"",MOD(DEGREES(ATAN2(COS(RADIANS(Q8))*SIN(RADIANS(X8)) - SIN(RADIANS(Q8))*COS(RADIANS(X8))*COS(RADIANS(Y8-R8)),COS(RADIANS(X8))*SIN(RADIANS(Y8-R8)))) + 360, 360)) | AB8: =IF('Recovery Log'!Y8="","",'Recovery Log'!Y8) | AC8: =IF('Recovery Log'!Z8="","",'Recovery Log'!Z8) | AD8: ='Recovery Log'!AA8 | AF8: =IF(ISBLANK(Q8),"",2*6370*ASIN(SQRT(SIN(RADIANS(Q8-J8)/2)*SIN(RADIANS(Q8-J8)/2) + COS(RADIANS(Q8))*COS(RADIANS(J8))*SIN(RADIANS(R8-K8)/2)*SIN(RADIANS(R8-K8)/2)))*1000) | AG8: =IF(ISBLANK(Q8),"",MOD(DEGREES(ATAN2(COS(RADIANS(J8))*SIN(RADIANS(Q8)) - SIN(RADIANS(J8))*COS(RADIANS(Q8))*COS(RADIANS(R8-K8)),COS(RADIANS(Q8))*SIN(RADIANS(R8-K8)))) + 360, 360)) | AH8: =IF('Recovery Log'!O8>'Deployment Log'!M8,'Recovery Log'!O8-'Deployment Log'!M8,"n/a") -> n/a | AI8: =IF(AND(ISNUMBER(G8),ISNUMBER(E8)),G8-E8,"n/a") -> n/a | AJ8: =IF(ISNUMBER(AH8),'Recovery Log'!AC8/AH8,"n/a") -> n/a | AK8: =IF(ISNUMBER(AJ8),1000000*AJ8/(24*60*60*1000),"n/a") -> n/a | AL8: =IF(ISNUMBER(AJ8),250+AJ8/24/60/60/250,"n/a") -> n/a | AM8: =IF(ISBLANK('Deployment Log'!AF8),"n/a",DEGREES(ATAN2('Deployment Log'!AF8,SQRT('Deployment Log'!AG8^2 + 'Deployment Log'!AH8^2)))) -> n/a | AN8: =IF(ISBLANK('Recovery Log'!P8),"n/a",DEGREES(ATAN2('Recovery Log'!P8,SQRT('Recovery Log'!Q8^2 + 'Recovery Log'!R8^2)))) -> n/a | AO8: =IF(AND(ISNUMBER(D8),ISNUMBER(E8)),(E8-D8)*24*60,"n/a") -> n/a | AP8: =IF(AND(ISNUMBER(G8),ISNUMBER(H8)),(H8-G8)*24*60,"n/a") -> n/a | AQ8: =IF(AND(ISNUMBER(G8),ISNUMBER('Recovery Log'!K8)),(G8-'Recovery Log'!K8)*24*60,"n/a") -> n/a | AR8: =IF(AND(ISNUMBER(H8),ISNUMBER(I8)),(I8-H8)*24*60,"n/a") -> n/a | AS8: =IF(AND(ISNUMBER('Recovery Log'!I8),ISNUMBER('Recovery Log'!N8)),('Recovery Log'!N8-'Recovery Log'!I8)*24*60,"n/a") -> n/a | AT8: =IF(ISNUMBER(AO8),O8/AO8,"n/a") -> n/a | AU8: =IF(ISNUMBER(AP8),O8/AP8,"n/a") -> n/a
A9: ='Deployment Log'!A9 -> 0 | B9: ='Deployment Log'!S9 -> 0 | C9: ='Deployment Log'!T9 -> 0 | D9: =IF('Deployment Log'!N9>DATE(2021,8,1),'Deployment Log'!N9,"n/a") -> n/a | E9: =IF('Deployment Log'!O9>DATE(2021,8,1),'Deployment Log'!O9,"n/a") -> n/a | F9: =IF('Deployment Log'!P9>DATE(2021,8,1),'Deployment Log'!P9,"n/a") -> n/a | G9: =IF('Recovery Log'!L9>DATE(2021,8,1),'Recovery Log'!L9,"n/a") -> n/a | H9: =IF('Recovery Log'!M9>DATE(2021,8,1),'Recovery Log'!M9,"n/a") -> n/a | I9: =IF(MIN('Recovery Log'!N9:O9)>DATE(2021,8,1),MIN('Recovery Log'!N9:O9),"n/a") -> n/a | J9: ='Deployment Log'!B9 -> 0 | K9: ='Deployment Log'!C9 -> 0 | L9: ='Deployment Log'!D9 -> 0 | M9: ='Deployment Log'!I9 -> 0 | N9: ='Deployment Log'!J9 -> 0 | O9: ='Deployment Log'!K9 -> 0 | P9: ='Deployment Log'!L9 | U9: =IF(ISBLANK(Q9),"",2*6370*ASIN(SQRT(SIN(RADIANS(Q9-M9)/2)*SIN(RADIANS(Q9-M9)/2) + COS(RADIANS(Q9))*COS(RADIANS(M9))*SIN(RADIANS(R9-N9)/2)*SIN(RADIANS(R9-N9)/2)))*1000) | V9: =ABS(U9/S9) -> #VALUE! | W9: =IF(ISBLANK(Q9),"",MOD(DEGREES(ATAN2(COS(RADIANS(M9))*SIN(RADIANS(Q9)) - SIN(RADIANS(M9))*COS(RADIANS(Q9))*COS(RADIANS(R9-N9)),COS(RADIANS(Q9))*SIN(RADIANS(R9-N9)))) + 360, 360)) | X9: =IF('Recovery Log'!V9="","",'Recovery Log'!V9) | Y9: =IF('Recovery Log'!W9="","",'Recovery Log'!W9) | Z9: ='Recovery Log'!X9 | AA9: =IF(ISBLANK(Q9),"",MOD(DEGREES(ATAN2(COS(RADIANS(Q9))*SIN(RADIANS(X9)) - SIN(RADIANS(Q9))*COS(RADIANS(X9))*COS(RADIANS(Y9-R9)),COS(RADIANS(X9))*SIN(RADIANS(Y9-R9)))) + 360, 360)) | AB9: =IF('Recovery Log'!Y9="","",'Recovery Log'!Y9) | AC9: =IF('Recovery Log'!Z9="","",'Recovery Log'!Z9) | AD9: ='Recovery Log'!AA9 | AF9: =IF(ISBLANK(Q9),"",2*6370*ASIN(SQRT(SIN(RADIANS(Q9-J9)/2)*SIN(RADIANS(Q9-J9)/2) + COS(RADIANS(Q9))*COS(RADIANS(J9))*SIN(RADIANS(R9-K9)/2)*SIN(RADIANS(R9-K9)/2)))*1000) | AG9: =IF(ISBLANK(Q9),"",MOD(DEGREES(ATAN2(COS(RADIANS(J9))*SIN(RADIANS(Q9)) - SIN(RADIANS(J9))*COS(RADIANS(Q9))*COS(RADIANS(R9-K9)),COS(RADIANS(Q9))*SIN(RADIANS(R9-K9)))) + 360, 360)) | AH9: =IF('Recovery Log'!O9>'Deployment Log'!M9,'Recovery Log'!O9-'Deployment Log'!M9,"n/a") -> n/a | AI9: =IF(AND(ISNUMBER(G9),ISNUMBER(E9)),G9-E9,"n/a") -> n/a | AJ9: =IF(ISNUMBER(AH9),'Recovery Log'!AC9/AH9,"n/a") -> n/a | AK9: =IF(ISNUMBER(AJ9),1000000*AJ9/(24*60*60*1000),"n/a") -> n/a | AL9: =IF(ISNUMBER(AJ9),250+AJ9/24/60/60/250,"n/a") -> n/a | AM9: =IF(ISBLANK('Deployment Log'!AF9),"n/a",DEGREES(ATAN2('Deployment Log'!AF9,SQRT('Deployment Log'!AG9^2 + 'Deployment Log'!AH9^2)))) -> n/a | AN9: =IF(ISBLANK('Recovery Log'!P9),"n/a",DEGREES(ATAN2('Recovery Log'!P9,SQRT('Recovery Log'!Q9^2 + 'Recovery Log'!R9^2)))) -> n/a | AO9: =IF(AND(ISNUMBER(D9),ISNUMBER(E9)),(E9-D9)*24*60,"n/a") -> n/a | AP9: =IF(AND(ISNUMBER(G9),ISNUMBER(H9)),(H9-G9)*24*60,"n/a") -> n/a | AQ9: =IF(AND(ISNUMBER(G9),ISNUMBER('Recovery Log'!K9)),(G9-'Recovery Log'!K9)*24*60,"n/a") -> n/a | AR9: =IF(AND(ISNUMBER(H9),ISNUMBER(I9)),(I9-H9)*24*60,"n/a") -> n/a | AS9: =IF(AND(ISNUMBER('Recovery Log'!I9),ISNUMBER('Recovery Log'!N9)),('Recovery Log'!N9-'Recovery Log'!I9)*24*60,"n/a") -> n/a | AT9: =IF(ISNUMBER(AO9),O9/AO9,"n/a") -> n/a | AU9: =IF(ISNUMBER(AP9),O9/AP9,"n/a") -> n/a
A10: ='Deployment Log'!A10 -> 0 | B10: ='Deployment Log'!S10 -> 0 | C10: ='Deployment Log'!T10 -> 0 | D10: =IF('Deployment Log'!N10>DATE(2021,8,1),'Deployment Log'!N10,"n/a") -> n/a | E10: =IF('Deployment Log'!O10>DATE(2021,8,1),'Deployment Log'!O10,"n/a") -> n/a | F10: =IF('Deployment Log'!P10>DATE(2021,8,1),'Deployment Log'!P10,"n/a") -> n/a | G10: =IF('Recovery Log'!L10>DATE(2021,8,1),'Recovery Log'!L10,"n/a") -> n/a | H10: =IF('Recovery Log'!M10>DATE(2021,8,1),'Recovery Log'!M10,"n/a") -> n/a | I10: =IF(MIN('Recovery Log'!N10:O10)>DATE(2021,8,1),MIN('Recovery Log'!N10:O10),"n/a") -> n/a | J10: ='Deployment Log'!B10 -> 0 | K10: ='Deployment Log'!C10 -> 0 | L10: ='Deployment Log'!D10 -> 0 | M10: ='Deployment Log'!I10 -> 0 | N10: ='Deployment Log'!J10 -> 0 | O10: ='Deployment Log'!K10 -> 0 | P10: ='Deployment Log'!L10 | U10: =IF(ISBLANK(Q10),"",2*6370*ASIN(SQRT(SIN(RADIANS(Q10-M10)/2)*SIN(RADIANS(Q10-M10)/2) + COS(RADIANS(Q10))*COS(RADIANS(M10))*SIN(RADIANS(R10-N10)/2)*SIN(RADIANS(R10-N10)/2)))*1000) | V10: =ABS(U10/S10) -> #VALUE! | W10: =IF(ISBLANK(Q10),"",MOD(DEGREES(ATAN2(COS(RADIANS(M10))*SIN(RADIANS(Q10)) - SIN(RADIANS(M10))*COS(RADIANS(Q10))*COS(RADIANS(R10-N10)),COS(RADIANS(Q10))*SIN(RADIANS(R10-N10)))) + 360, 360)) | X10: =IF('Recovery Log'!V10="","",'Recovery Log'!V10) | Y10: =IF('Recovery Log'!W10="","",'Recovery Log'!W10) | Z10: ='Recovery Log'!X10 | AA10: =IF(ISBLANK(Q10),"",MOD(DEGREES(ATAN2(COS(RADIANS(Q10))*SIN(RADIANS(X10)) - SIN(RADIANS(Q10))*COS(RADIANS(X10))*COS(RADIANS(Y10-R10)),COS(RADIANS(X10))*SIN(RADIANS(Y10-R10)))) + 360, 360)) | AB10: =IF('Recovery Log'!Y10="","",'Recovery Log'!Y10) | AC10: =IF('Recovery Log'!Z10="","",'Recovery Log'!Z10) | AD10: ='Recovery Log'!AA10 | AF10: =IF(ISBLANK(Q10),"",2*6370*ASIN(SQRT(SIN(RADIANS(Q10-J10)/2)*SIN(RADIANS(Q10-J10)/2) + COS(RADIANS(Q10))*COS(RADIANS(J10))*SIN(RADIANS(R10-K10)/2)*SIN(RADIANS(R10-K10)/2)))*1000) | AG10: =IF(ISBLANK(Q10),"",MOD(DEGREES(ATAN2(COS(RADIANS(J10))*SIN(RADIANS(Q10)) - SIN(RADIANS(J10))*COS(RADIANS(Q10))*COS(RADIANS(R10-K10)),COS(RADIANS(Q10))*SIN(RADIANS(R10-K10)))) + 360, 360)) | AH10: =IF('Recovery Log'!O10>'Deployment Log'!M10,'Recovery Log'!O10-'Deployment Log'!M10,"n/a") -> n/a | AI10: =IF(AND(ISNUMBER(G10),ISNUMBER(E10)),G10-E10,"n/a") -> n/a | AJ10: =IF(ISNUMBER(AH10),'Recovery Log'!AC10/AH10,"n/a") -> n/a | AK10: =IF(ISNUMBER(AJ10),1000000*AJ10/(24*60*60*1000),"n/a") -> n/a | AL10: =IF(ISNUMBER(AJ10),250+AJ10/24/60/60/250,"n/a") -> n/a | AM10: =IF(ISBLANK('Deployment Log'!AF10),"n/a",DEGREES(ATAN2('Deployment Log'!AF10,SQRT('Deployment Log'!AG10^2 + 'Deployment Log'!AH10^2)))) -> n/a | AN10: =IF(ISBLANK('Recovery Log'!P10),"n/a",DEGREES(ATAN2('Recovery Log'!P10,SQRT('Recovery Log'!Q10^2 + 'Recovery Log'!R10^2)))) -> n/a | AO10: =IF(AND(ISNUMBER(D10),ISNUMBER(E10)),(E10-D10)*24*60,"n/a") -> n/a | AP10: =IF(AND(ISNUMBER(G10),ISNUMBER(H10)),(H10-G10)*24*60,"n/a") -> n/a | AQ10: =IF(AND(ISNUMBER(G10),ISNUMBER('Recovery Log'!K10)),(G10-'Recovery Log'!K10)*24*60,"n/a") -> n/a | AR10: =IF(AND(ISNUMBER(H10),ISNUMBER(I10)),(I10-H10)*24*60,"n/a") -> n/a | AS10: =IF(AND(ISNUMBER('Recovery Log'!I10),ISNUMBER('Recovery Log'!N10)),('Recovery Log'!N10-'Recovery Log'!I10)*24*60,"n/a") -> n/a | AT10: =IF(ISNUMBER(AO10),O10/AO10,"n/a") -> n/a | AU10: =IF(ISNUMBER(AP10),O10/AP10,"n/a") -> n/a
A11: ='Deployment Log'!A11 -> 0 | B11: ='Deployment Log'!S11 -> 0 | C11: ='Deployment Log'!T11 -> 0 | D11: =IF('Deployment Log'!N11>DATE(2021,8,1),'Deployment Log'!N11,"n/a") -> n/a | E11: =IF('Deployment Log'!O11>DATE(2021,8,1),'Deployment Log'!O11,"n/a") -> n/a | F11: =IF('Deployment Log'!P11>DATE(2021,8,1),'Deployment Log'!P11,"n/a") -> n/a | G11: =IF('Recovery Log'!L11>DATE(2021,8,1),'Recovery Log'!L11,"n/a") -> n/a | H11: =IF('Recovery Log'!M11>DATE(2021,8,1),'Recovery Log'!M11,"n/a") -> n/a | I11: =IF(MIN('Recovery Log'!N11:O11)>DATE(2021,8,1),MIN('Recovery Log'!N11:O11),"n/a") -> n/a | J11: ='Deployment Log'!B11 -> 0 | K11: ='Deployment Log'!C11 -> 0 | L11: ='Deployment Log'!D11 -> 0 | M11: ='Deployment Log'!I11 -> 0 | N11: ='Deployment Log'!J11 -> 0 | O11: ='Deployment Log'!K11 -> 0 | P11: ='Deployment Log'!L11 | U11: =IF(ISBLANK(Q11),"",2*6370*ASIN(SQRT(SIN(RADIANS(Q11-M11)/2)*SIN(RADIANS(Q11-M11)/2) + COS(RADIANS(Q11))*COS(RADIANS(M11))*SIN(RADIANS(R11-N11)/2)*SIN(RADIANS(R11-N11)/2)))*1000) | V11: =ABS(U11/S11) -> #VALUE! | W11: =IF(ISBLANK(Q11),"",MOD(DEGREES(ATAN2(COS(RADIANS(M11))*SIN(RADIANS(Q11)) - SIN(RADIANS(M11))*COS(RADIANS(Q11))*COS(RADIANS(R11-N11)),COS(RADIANS(Q11))*SIN(RADIANS(R11-N11)))) + 360, 360)) | X11: =IF('Recovery Log'!V11="","",'Recovery Log'!V11) | Y11: =IF('Recovery Log'!W11="","",'Recovery Log'!W11) | Z11: ='Recovery Log'!X11 | AA11: =IF(ISBLANK(Q11),"",MOD(DEGREES(ATAN2(COS(RADIANS(Q11))*SIN(RADIANS(X11)) - SIN(RADIANS(Q11))*COS(RADIANS(X11))*COS(RADIANS(Y11-R11)),COS(RADIANS(X11))*SIN(RADIANS(Y11-R11)))) + 360, 360)) | AB11: =IF('Recovery Log'!Y11="","",'Recovery Log'!Y11) | AC11: =IF('Recovery Log'!Z11="","",'Recovery Log'!Z11) | AD11: ='Recovery Log'!AA11 | AF11: =IF(ISBLANK(Q11),"",2*6370*ASIN(SQRT(SIN(RADIANS(Q11-J11)/2)*SIN(RADIANS(Q11-J11)/2) + COS(RADIANS(Q11))*COS(RADIANS(J11))*SIN(RADIANS(R11-K11)/2)*SIN(RADIANS(R11-K11)/2)))*1000) | AG11: =IF(ISBLANK(Q11),"",MOD(DEGREES(ATAN2(COS(RADIANS(J11))*SIN(RADIANS(Q11)) - SIN(RADIANS(J11))*COS(RADIANS(Q11))*COS(RADIANS(R11-K11)),COS(RADIANS(Q11))*SIN(RADIANS(R11-K11)))) + 360, 360)) | AH11: =IF('Recovery Log'!O11>'Deployment Log'!M11,'Recovery Log'!O11-'Deployment Log'!M11,"n/a") -> n/a | AI11: =IF(AND(ISNUMBER(G11),ISNUMBER(E11)),G11-E11,"n/a") -> n/a | AJ11: =IF(ISNUMBER(AH11),'Recovery Log'!AC11/AH11,"n/a") -> n/a | AK11: =IF(ISNUMBER(AJ11),1000000*AJ11/(24*60*60*1000),"n/a") -> n/a | AL11: =IF(ISNUMBER(AJ11),250+AJ11/24/60/60/250,"n/a") -> n/a | AM11: =IF(ISBLANK('Deployment Log'!AF11),"n/a",DEGREES(ATAN2('Deployment Log'!AF11,SQRT('Deployment Log'!AG11^2 + 'Deployment Log'!AH11^2)))) -> n/a | AN11: =IF(ISBLANK('Recovery Log'!P11),"n/a",DEGREES(ATAN2('Recovery Log'!P11,SQRT('Recovery Log'!Q11^2 + 'Recovery Log'!R11^2)))) -> n/a | AO11: =IF(AND(ISNUMBER(D11),ISNUMBER(E11)),(E11-D11)*24*60,"n/a") -> n/a | AP11: =IF(AND(ISNUMBER(G11),ISNUMBER(H11)),(H11-G11)*24*60,"n/a") -> n/a | AQ11: =IF(AND(ISNUMBER(G11),ISNUMBER('Recovery Log'!K11)),(G11-'Recovery Log'!K11)*24*60,"n/a") -> n/a | AR11: =IF(AND(ISNUMBER(H11),ISNUMBER(I11)),(I11-H11)*24*60,"n/a") -> n/a | AS11: =IF(AND(ISNUMBER('Recovery Log'!I11),ISNUMBER('Recovery Log'!N11)),('Recovery Log'!N11-'Recovery Log'!I11)*24*60,"n/a") -> n/a | AT11: =IF(ISNUMBER(AO11),O11/AO11,"n/a") -> n/a | AU11: =IF(ISNUMBER(AP11),O11/AP11,"n/a") -> n/a
A12: ='Deployment Log'!A12 -> 0 | B12: ='Deployment Log'!S12 -> 0 | C12: ='Deployment Log'!T12 -> 0 | D12: =IF('Deployment Log'!N12>DATE(2021,8,1),'Deployment Log'!N12,"n/a") -> n/a | E12: =IF('Deployment Log'!O12>DATE(2021,8,1),'Deployment Log'!O12,"n/a") -> n/a | F12: =IF('Deployment Log'!P12>DATE(2021,8,1),'Deployment Log'!P12,"n/a") -> n/a | G12: =IF('Recovery Log'!L12>DATE(2021,8,1),'Recovery Log'!L12,"n/a") -> n/a | H12: =IF('Recovery Log'!M12>DATE(2021,8,1),'Recovery Log'!M12,"n/a") -> n/a | I12: =IF(MIN('Recovery Log'!N12:O12)>DATE(2021,8,1),MIN('Recovery Log'!N12:O12),"n/a") -> n/a | J12: ='Deployment Log'!B12 -> 0 | K12: ='Deployment Log'!C12 -> 0 | L12: ='Deployment Log'!D12 -> 0 | M12: ='Deployment Log'!I12 -> 0 | N12: ='Deployment Log'!J12 -> 0 | O12: ='Deployment Log'!K12 -> 0 | P12: ='Deployment Log'!L12 | U12: =IF(ISBLANK(Q12),"",2*6370*ASIN(SQRT(SIN(RADIANS(Q12-M12)/2)*SIN(RADIANS(Q12-M12)/2) + COS(RADIANS(Q12))*COS(RADIANS(M12))*SIN(RADIANS(R12-N12)/2)*SIN(RADIANS(R12-N12)/2)))*1000) | V12: =ABS(U12/S12) -> #VALUE! | W12: =IF(ISBLANK(Q12),"",MOD(DEGREES(ATAN2(COS(RADIANS(M12))*SIN(RADIANS(Q12)) - SIN(RADIANS(M12))*COS(RADIANS(Q12))*COS(RADIANS(R12-N12)),COS(RADIANS(Q12))*SIN(RADIANS(R12-N12)))) + 360, 360)) | X12: =IF('Recovery Log'!V12="","",'Recovery Log'!V12) | Y12: =IF('Recovery Log'!W12="","",'Recovery Log'!W12) | Z12: ='Recovery Log'!X12 | AA12: =IF(ISBLANK(Q12),"",MOD(DEGREES(ATAN2(COS(RADIANS(Q12))*SIN(RADIANS(X12)) - SIN(RADIANS(Q12))*COS(RADIANS(X12))*COS(RADIANS(Y12-R12)),COS(RADIANS(X12))*SIN(RADIANS(Y12-R12)))) + 360, 360)) | AB12: =IF('Recovery Log'!Y12="","",'Recovery Log'!Y12) | AC12: =IF('Recovery Log'!Z12="","",'Recovery Log'!Z12) | AD12: ='Recovery Log'!AA12 | AF12: =IF(ISBLANK(Q12),"",2*6370*ASIN(SQRT(SIN(RADIANS(Q12-J12)/2)*SIN(RADIANS(Q12-J12)/2) + COS(RADIANS(Q12))*COS(RADIANS(J12))*SIN(RADIANS(R12-K12)/2)*SIN(RADIANS(R12-K12)/2)))*1000) | AG12: =IF(ISBLANK(Q12),"",MOD(DEGREES(ATAN2(COS(RADIANS(J12))*SIN(RADIANS(Q12)) - SIN(RADIANS(J12))*COS(RADIANS(Q12))*COS(RADIANS(R12-K12)),COS(RADIANS(Q12))*SIN(RADIANS(R12-K12)))) + 360, 360)) | AH12: =IF('Recovery Log'!O12>'Deployment Log'!M12,'Recovery Log'!O12-'Deployment Log'!M12,"n/a") -> n/a | AI12: =IF(AND(ISNUMBER(G12),ISNUMBER(E12)),G12-E12,"n/a") -> n/a | AJ12: =IF(ISNUMBER(AH12),'Recovery Log'!AC12/AH12,"n/a") -> n/a | AK12: =IF(ISNUMBER(AJ12),1000000*AJ12/(24*60*60*1000),"n/a") -> n/a | AL12: =IF(ISNUMBER(AJ12),250+AJ12/24/60/60/250,"n/a") -> n/a | AM12: =IF(ISBLANK('Deployment Log'!AF12),"n/a",DEGREES(ATAN2('Deployment Log'!AF12,SQRT('Deployment Log'!AG12^2 + 'Deployment Log'!AH12^2)))) -> n/a | AN12: =IF(ISBLANK('Recovery Log'!P12),"n/a",DEGREES(ATAN2('Recovery Log'!P12,SQRT('Recovery Log'!Q12^2 + 'Recovery Log'!R12^2)))) -> n/a | AO12: =IF(AND(ISNUMBER(D12),ISNUMBER(E12)),(E12-D12)*24*60,"n/a") -> n/a | AP12: =IF(AND(ISNUMBER(G12),ISNUMBER(H12)),(H12-G12)*24*60,"n/a") -> n/a | AQ12: =IF(AND(ISNUMBER(G12),ISNUMBER('Recovery Log'!K12)),(G12-'Recovery Log'!K12)*24*60,"n/a") -> n/a | AR12: =IF(AND(ISNUMBER(H12),ISNUMBER(I12)),(I12-H12)*24*60,"n/a") -> n/a | AS12: =IF(AND(ISNUMBER('Recovery Log'!I12),ISNUMBER('Recovery Log'!N12)),('Recovery Log'!N12-'Recovery Log'!I12)*24*60,"n/a") -> n/a | AT12: =IF(ISNUMBER(AO12),O12/AO12,"n/a") -> n/a | AU12: =IF(ISNUMBER(AP12),O12/AP12,"n/a") -> n/a
A13: ='Deployment Log'!A13 -> 0 | B13: ='Deployment Log'!S13 -> 0 | C13: ='Deployment Log'!T13 -> 0 | D13: =IF('Deployment Log'!N13>DATE(2021,8,1),'Deployment Log'!N13,"n/a") -> n/a | E13: =IF('Deployment Log'!O13>DATE(2021,8,1),'Deployment Log'!O13,"n/a") -> n/a | F13: =IF('Deployment Log'!P13>DATE(2021,8,1),'Deployment Log'!P13,"n/a") -> n/a | G13: =IF('Recovery Log'!L13>DATE(2021,8,1),'Recovery Log'!L13,"n/a") -> n/a | H13: =IF('Recovery Log'!M13>DATE(2021,8,1),'Recovery Log'!M13,"n/a") -> n/a | I13: =IF(MIN('Recovery Log'!N13:O13)>DATE(2021,8,1),MIN('Recovery Log'!N13:O13),"n/a") -> n/a | J13: ='Deployment Log'!B13 -> 0 | K13: ='Deployment Log'!C13 -> 0 | L13: ='Deployment Log'!D13 -> 0 | M13: ='Deployment Log'!I13 -> 0 | N13: ='Deployment Log'!J13 -> 0 | O13: ='Deployment Log'!K13 -> 0 | P13: ='Deployment Log'!L13 | U13: =IF(ISBLANK(Q13),"",2*6370*ASIN(SQRT(SIN(RADIANS(Q13-M13)/2)*SIN(RADIANS(Q13-M13)/2) + COS(RADIANS(Q13))*COS(RADIANS(M13))*SIN(RADIANS(R13-N13)/2)*SIN(RADIANS(R13-N13)/2)))*1000) | V13: =ABS(U13/S13) -> #VALUE! | W13: =IF(ISBLANK(Q13),"",MOD(DEGREES(ATAN2(COS(RADIANS(M13))*SIN(RADIANS(Q13)) - SIN(RADIANS(M13))*COS(RADIANS(Q13))*COS(RADIANS(R13-N13)),COS(RADIANS(Q13))*SIN(RADIANS(R13-N13)))) + 360, 360)) | X13: =IF('Recovery Log'!V13="","",'Recovery Log'!V13) | Y13: =IF('Recovery Log'!W13="","",'Recovery Log'!W13) | Z13: ='Recovery Log'!X13 | AA13: =IF(ISBLANK(Q13),"",MOD(DEGREES(ATAN2(COS(RADIANS(Q13))*SIN(RADIANS(X13)) - SIN(RADIANS(Q13))*COS(RADIANS(X13))*COS(RADIANS(Y13-R13)),COS(RADIANS(X13))*SIN(RADIANS(Y13-R13)))) + 360, 360)) | AB13: =IF('Recovery Log'!Y13="","",'Recovery Log'!Y13) | AC13: =IF('Recovery Log'!Z13="","",'Recovery Log'!Z13) | AD13: ='Recovery Log'!AA13 | AF13: =IF(ISBLANK(Q13),"",2*6370*ASIN(SQRT(SIN(RADIANS(Q13-J13)/2)*SIN(RADIANS(Q13-J13)/2) + COS(RADIANS(Q13))*COS(RADIANS(J13))*SIN(RADIANS(R13-K13)/2)*SIN(RADIANS(R13-K13)/2)))*1000) | AG13: =IF(ISBLANK(Q13),"",MOD(DEGREES(ATAN2(COS(RADIANS(J13))*SIN(RADIANS(Q13)) - SIN(RADIANS(J13))*COS(RADIANS(Q13))*COS(RADIANS(R13-K13)),COS(RADIANS(Q13))*SIN(RADIANS(R13-K13)))) + 360, 360)) | AH13: =IF('Recovery Log'!O13>'Deployment Log'!M13,'Recovery Log'!O13-'Deployment Log'!M13,"n/a") -> n/a | AI13: =IF(AND(ISNUMBER(G13),ISNUMBER(E13)),G13-E13,"n/a") -> n/a | AJ13: =IF(ISNUMBER(AH13),'Recovery Log'!AC13/AH13,"n/a") -> n/a | AK13: =IF(ISNUMBER(AJ13),1000000*AJ13/(24*60*60*1000),"n/a") -> n/a | AL13: =IF(ISNUMBER(AJ13),250+AJ13/24/60/60/250,"n/a") -> n/a | AM13: =IF(ISBLANK('Deployment Log'!AF13),"n/a",DEGREES(ATAN2('Deployment Log'!AF13,SQRT('Deployment Log'!AG13^2 + 'Deployment Log'!AH13^2)))) -> n/a | AN13: =IF(ISBLANK('Recovery Log'!P13),"n/a",DEGREES(ATAN2('Recovery Log'!P13,SQRT('Recovery Log'!Q13^2 + 'Recovery Log'!R13^2)))) -> n/a | AO13: =IF(AND(ISNUMBER(D13),ISNUMBER(E13)),(E13-D13)*24*60,"n/a") -> n/a | AP13: =IF(AND(ISNUMBER(G13),ISNUMBER(H13)),(H13-G13)*24*60,"n/a") -> n/a | AQ13: =IF(AND(ISNUMBER(G13),ISNUMBER('Recovery Log'!K13)),(G13-'Recovery Log'!K13)*24*60,"n/a") -> n/a | AR13: =IF(AND(ISNUMBER(H13),ISNUMBER(I13)),(I13-H13)*24*60,"n/a") -> n/a | AS13: =IF(AND(ISNUMBER('Recovery Log'!I13),ISNUMBER('Recovery Log'!N13)),('Recovery Log'!N13-'Recovery Log'!I13)*24*60,"n/a") -> n/a | AT13: =IF(ISNUMBER(AO13),O13/AO13,"n/a") -> n/a | AU13: =IF(ISNUMBER(AP13),O13/AP13,"n/a") -> n/a
A14: ='Deployment Log'!A14 -> 0 | B14: ='Deployment Log'!S14 -> 0 | C14: ='Deployment Log'!T14 -> 0 | D14: =IF('Deployment Log'!N14>DATE(2021,8,1),'Deployment Log'!N14,"n/a") -> n/a | E14: =IF('Deployment Log'!O14>DATE(2021,8,1),'Deployment Log'!O14,"n/a") -> n/a | F14: =IF('Deployment Log'!P14>DATE(2021,8,1),'Deployment Log'!P14,"n/a") -> n/a | G14: =IF('Recovery Log'!L14>DATE(2021,8,1),'Recovery Log'!L14,"n/a") -> n/a | H14: =IF('Recovery Log'!M14>DATE(2021,8,1),'Recovery Log'!M14,"n/a") -> n/a | I14: =IF(MIN('Recovery Log'!N14:O14)>DATE(2021,8,1),MIN('Recovery Log'!N14:O14),"n/a") -> n/a | J14: ='Deployment Log'!B14 -> 0 | K14: ='Deployment Log'!C14 -> 0 | L14: ='Deployment Log'!D14 -> 0 | M14: ='Deployment Log'!I14 -> 0 | N14: ='Deployment Log'!J14 -> 0 | O14: ='Deployment Log'!K14 -> 0 | P14: ='Deployment Log'!L14 | U14: =IF(ISBLANK(Q14),"",2*6370*ASIN(SQRT(SIN(RADIANS(Q14-M14)/2)*SIN(RADIANS(Q14-M14)/2) + COS(RADIANS(Q14))*COS(RADIANS(M14))*SIN(RADIANS(R14-N14)/2)*SIN(RADIANS(R14-N14)/2)))*1000) | V14: =ABS(U14/S14) -> #VALUE! | W14: =IF(ISBLANK(Q14),"",MOD(DEGREES(ATAN2(COS(RADIANS(M14))*SIN(RADIANS(Q14)) - SIN(RADIANS(M14))*COS(RADIANS(Q14))*COS(RADIANS(R14-N14)),COS(RADIANS(Q14))*SIN(RADIANS(R14-N14)))) + 360, 360)) | X14: =IF('Recovery Log'!V14="","",'Recovery Log'!V14) | Y14: =IF('Recovery Log'!W14="","",'Recovery Log'!W14) | Z14: ='Recovery Log'!X14 | AA14: =IF(ISBLANK(Q14),"",MOD(DEGREES(ATAN2(COS(RADIANS(Q14))*SIN(RADIANS(X14)) - SIN(RADIANS(Q14))*COS(RADIANS(X14))*COS(RADIANS(Y14-R14)),COS(RADIANS(X14))*SIN(RADIANS(Y14-R14)))) + 360, 360)) | AB14: =IF('Recovery Log'!Y14="","",'Recovery Log'!Y14) | AC14: =IF('Recovery Log'!Z14="","",'Recovery Log'!Z14) | AD14: ='Recovery Log'!AA14 | AF14: =IF(ISBLANK(Q14),"",2*6370*ASIN(SQRT(SIN(RADIANS(Q14-J14)/2)*SIN(RADIANS(Q14-J14)/2) + COS(RADIANS(Q14))*COS(RADIANS(J14))*SIN(RADIANS(R14-K14)/2)*SIN(RADIANS(R14-K14)/2)))*1000) | AG14: =IF(ISBLANK(Q14),"",MOD(DEGREES(ATAN2(COS(RADIANS(J14))*SIN(RADIANS(Q14)) - SIN(RADIANS(J14))*COS(RADIANS(Q14))*COS(RADIANS(R14-K14)),COS(RADIANS(Q14))*SIN(RADIANS(R14-K14)))) + 360, 360)) | AH14: =IF('Recovery Log'!O14>'Deployment Log'!M14,'Recovery Log'!O14-'Deployment Log'!M14,"n/a") -> n/a | AI14: =IF(AND(ISNUMBER(G14),ISNUMBER(E14)),G14-E14,"n/a") -> n/a | AJ14: =IF(ISNUMBER(AH14),'Recovery Log'!AC14/AH14,"n/a") -> n/a | AK14: =IF(ISNUMBER(AJ14),1000000*AJ14/(24*60*60*1000),"n/a") -> n/a | AL14: =IF(ISNUMBER(AJ14),250+AJ14/24/60/60/250,"n/a") -> n/a | AM14: =IF(ISBLANK('Deployment Log'!AF14),"n/a",DEGREES(ATAN2('Deployment Log'!AF14,SQRT('Deployment Log'!AG14^2 + 'Deployment Log'!AH14^2)))) -> n/a | AN14: =IF(ISBLANK('Recovery Log'!P14),"n/a",DEGREES(ATAN2('Recovery Log'!P14,SQRT('Recovery Log'!Q14^2 + 'Recovery Log'!R14^2)))) -> n/a | AO14: =IF(AND(ISNUMBER(D14),ISNUMBER(E14)),(E14-D14)*24*60,"n/a") -> n/a | AP14: =IF(AND(ISNUMBER(G14),ISNUMBER(H14)),(H14-G14)*24*60,"n/a") -> n/a | AQ14: =IF(AND(ISNUMBER(G14),ISNUMBER('Recovery Log'!K14)),(G14-'Recovery Log'!K14)*24*60,"n/a") -> n/a | AR14: =IF(AND(ISNUMBER(H14),ISNUMBER(I14)),(I14-H14)*24*60,"n/a") -> n/a | AS14: =IF(AND(ISNUMBER('Recovery Log'!I14),ISNUMBER('Recovery Log'!N14)),('Recovery Log'!N14-'Recovery Log'!I14)*24*60,"n/a") -> n/a | AT14: =IF(ISNUMBER(AO14),O14/AO14,"n/a") -> n/a | AU14: =IF(ISNUMBER(AP14),O14/AP14,"n/a") -> n/a
A15: ='Deployment Log'!A15 -> 0 | B15: ='Deployment Log'!S15 -> 0 | C15: ='Deployment Log'!T15 -> 0 | D15: =IF('Deployment Log'!N15>DATE(2021,8,1),'Deployment Log'!N15,"n/a") -> n/a | E15: =IF('Deployment Log'!O15>DATE(2021,8,1),'Deployment Log'!O15,"n/a") -> n/a | F15: =IF('Deployment Log'!P15>DATE(2021,8,1),'Deployment Log'!P15,"n/a") -> n/a | G15: =IF('Recovery Log'!L15>DATE(2021,8,1),'Recovery Log'!L15,"n/a") -> n/a | H15: =IF('Recovery Log'!M15>DATE(2021,8,1),'Recovery Log'!M15,"n/a") -> n/a | I15: =IF(MIN('Recovery Log'!N15:O15)>DATE(2021,8,1),MIN('Recovery Log'!N15:O15),"n/a") -> n/a | J15: ='Deployment Log'!B15 -> 0 | K15: ='Deployment Log'!C15 -> 0 | L15: ='Deployment Log'!D15 -> 0 | M15: ='Deployment Log'!I15 -> 0 | N15: ='Deployment Log'!J15 -> 0 | O15: ='Deployment Log'!K15 -> 0 | P15: ='Deployment Log'!L15 | U15: =IF(ISBLANK(Q15),"",2*6370*ASIN(SQRT(SIN(RADIANS(Q15-M15)/2)*SIN(RADIANS(Q15-M15)/2) + COS(RADIANS(Q15))*COS(RADIANS(M15))*SIN(RADIANS(R15-N15)/2)*SIN(RADIANS(R15-N15)/2)))*1000) | V15: =ABS(U15/S15) -> #VALUE! | W15: =IF(ISBLANK(Q15),"",MOD(DEGREES(ATAN2(COS(RADIANS(M15))*SIN(RADIANS(Q15)) - SIN(RADIANS(M15))*COS(RADIANS(Q15))*COS(RADIANS(R15-N15)),COS(RADIANS(Q15))*SIN(RADIANS(R15-N15)))) + 360, 360)) | X15: =IF('Recovery Log'!V15="","",'Recovery Log'!V15) | Y15: =IF('Recovery Log'!W15="","",'Recovery Log'!W15) | Z15: ='Recovery Log'!X15 | AA15: =IF(ISBLANK(Q15),"",MOD(DEGREES(ATAN2(COS(RADIANS(Q15))*SIN(RADIANS(X15)) - SIN(RADIANS(Q15))*COS(RADIANS(X15))*COS(RADIANS(Y15-R15)),COS(RADIANS(X15))*SIN(RADIANS(Y15-R15)))) + 360, 360)) | AB15: =IF('Recovery Log'!Y15="","",'Recovery Log'!Y15) | AC15: =IF('Recovery Log'!Z15="","",'Recovery Log'!Z15) | AD15: ='Recovery Log'!AA15 | AF15: =IF(ISBLANK(Q15),"",2*6370*ASIN(SQRT(SIN(RADIANS(Q15-J15)/2)*SIN(RADIANS(Q15-J15)/2) + COS(RADIANS(Q15))*COS(RADIANS(J15))*SIN(RADIANS(R15-K15)/2)*SIN(RADIANS(R15-K15)/2)))*1000) | AG15: =IF(ISBLANK(Q15),"",MOD(DEGREES(ATAN2(COS(RADIANS(J15))*SIN(RADIANS(Q15)) - SIN(RADIANS(J15))*COS(RADIANS(Q15))*COS(RADIANS(R15-K15)),COS(RADIANS(Q15))*SIN(RADIANS(R15-K15)))) + 360, 360)) | AH15: =IF('Recovery Log'!O15>'Deployment Log'!M15,'Recovery Log'!O15-'Deployment Log'!M15,"n/a") -> n/a | AI15: =IF(AND(ISNUMBER(G15),ISNUMBER(E15)),G15-E15,"n/a") -> n/a | AJ15: =IF(ISNUMBER(AH15),'Recovery Log'!AC15/AH15,"n/a") -> n/a | AK15: =IF(ISNUMBER(AJ15),1000000*AJ15/(24*60*60*1000),"n/a") -> n/a | AL15: =IF(ISNUMBER(AJ15),250+AJ15/24/60/60/250,"n/a") -> n/a | AM15: =IF(ISBLANK('Deployment Log'!AF15),"n/a",DEGREES(ATAN2('Deployment Log'!AF15,SQRT('Deployment Log'!AG15^2 + 'Deployment Log'!AH15^2)))) -> n/a | AN15: =IF(ISBLANK('Recovery Log'!P15),"n/a",DEGREES(ATAN2('Recovery Log'!P15,SQRT('Recovery Log'!Q15^2 + 'Recovery Log'!R15^2)))) -> n/a | AO15: =IF(AND(ISNUMBER(D15),ISNUMBER(E15)),(E15-D15)*24*60,"n/a") -> n/a | AP15: =IF(AND(ISNUMBER(G15),ISNUMBER(H15)),(H15-G15)*24*60,"n/a") -> n/a | AQ15: =IF(AND(ISNUMBER(G15),ISNUMBER('Recovery Log'!K15)),(G15-'Recovery Log'!K15)*24*60,"n/a") -> n/a | AR15: =IF(AND(ISNUMBER(H15),ISNUMBER(I15)),(I15-H15)*24*60,"n/a") -> n/a | AS15: =IF(AND(ISNUMBER('Recovery Log'!I15),ISNUMBER('Recovery Log'!N15)),('Recovery Log'!N15-'Recovery Log'!I15)*24*60,"n/a") -> n/a | AT15: =IF(ISNUMBER(AO15),O15/AO15,"n/a") -> n/a | AU15: =IF(ISNUMBER(AP15),O15/AP15,"n/a") -> n/a
... A22: ='Deployment Log'!A22 -> 0 | B22: ='Deployment Log'!S22 -> 0 | C22: ='Deployment Log'!T22 -> 0 | D22: =IF('Deployment Log'!N22>DATE(2021,8,1),'Deployment Log'!N22,"n/a") -> n/a | E22: =IF('Deployment Log'!O22>DATE(2021,8,1),'Deployment Log'!O22,"n/a") -> n/a | F22: =IF('Deployment Log'!P22>DATE(2021,8,1),'Deployment Log'!P22,"n/a") -> n/a | G22: =IF('Recovery Log'!L22>DATE(2021,8,1),'Recovery Log'!L22,"n/a") -> n/a | H22: =IF('Recovery Log'!M22>DATE(2021,8,1),'Recovery Log'!M22,"n/a") -> n/a | I22: =IF(MIN('Recovery Log'!N22:O22)>DATE(2021,8,1),MIN('Recovery Log'!N22:O22),"n/a") -> n/a | J22: ='Deployment Log'!B22 -> 0 | K22: ='Deployment Log'!C22 -> 0 | L22: ='Deployment Log'!D22 -> 0 | M22: ='Deployment Log'!I22 -> 0 | N22: ='Deployment Log'!J22 -> 0 | O22: ='Deployment Log'!K22 -> 0 | P22: ='Deployment Log'!L22 | U22: =IF(ISBLANK(Q22),"",2*6370*ASIN(SQRT(SIN(RADIANS(Q22-M22)/2)*SIN(RADIANS(Q22-M22)/2) + COS(RADIANS(Q22))*COS(RADIANS(M22))*SIN(RADIANS(R22-N22)/2)*SIN(RADIANS(R22-N22)/2)))*1000) | V22: =ABS(U22/S22) -> #VALUE! | W22: =IF(ISBLANK(Q22),"",MOD(DEGREES(ATAN2(COS(RADIANS(M22))*SIN(RADIANS(Q22)) - SIN(RADIANS(M22))*COS(RADIANS(Q22))*COS(RADIANS(R22-N22)),COS(RADIANS(Q22))*SIN(RADIANS(R22-N22)))) + 360, 360)) | X22: =IF('Recovery Log'!V22="","",'Recovery Log'!V22) | Y22: =IF('Recovery Log'!W22="","",'Recovery Log'!W22) | Z22: ='Recovery Log'!X22 | AA22: =IF(ISBLANK(Q22),"",MOD(DEGREES(ATAN2(COS(RADIANS(Q22))*SIN(RADIANS(X22)) - SIN(RADIANS(Q22))*COS(RADIANS(X22))*COS(RADIANS(Y22-R22)),COS(RADIANS(X22))*SIN(RADIANS(Y22-R22)))) + 360, 360)) | AB22: =IF('Recovery Log'!Y22="","",'Recovery Log'!Y22) | AC22: =IF('Recovery Log'!Z22="","",'Recovery Log'!Z22) | AD22: ='Recovery Log'!AA22 | AF22: =IF(ISBLANK(Q22),"",2*6370*ASIN(SQRT(SIN(RADIANS(Q22-J22)/2)*SIN(RADIANS(Q22-J22)/2) + COS(RADIANS(Q22))*COS(RADIANS(J22))*SIN(RADIANS(R22-K22)/2)*SIN(RADIANS(R22-K22)/2)))*1000) | AG22: =IF(ISBLANK(Q22),"",MOD(DEGREES(ATAN2(COS(RADIANS(J22))*SIN(RADIANS(Q22)) - SIN(RADIANS(J22))*COS(RADIANS(Q22))*COS(RADIANS(R22-K22)),COS(RADIANS(Q22))*SIN(RADIANS(R22-K22)))) + 360, 360)) | AH22: =IF('Recovery Log'!O22>'Deployment Log'!M22,'Recovery Log'!O22-'Deployment Log'!M22,"n/a") -> n/a | AI22: =IF(AND(ISNUMBER(G22),ISNUMBER(E22)),G22-E22,"n/a") -> n/a | AJ22: =IF(ISNUMBER(AH22),'Recovery Log'!AC22/AH22,"n/a") -> n/a | AK22: =IF(ISNUMBER(AJ22),1000000*AJ22/(24*60*60*1000),"n/a") -> n/a | AL22: =IF(ISNUMBER(AJ22),250+AJ22/24/60/60/250,"n/a") -> n/a | AM22: =IF(ISBLANK('Deployment Log'!AF22),"n/a",DEGREES(ATAN2('Deployment Log'!AF22,SQRT('Deployment Log'!AG22^2 + 'Deployment Log'!AH22^2)))) -> n/a | AN22: =IF(ISBLANK('Recovery Log'!P22),"n/a",DEGREES(ATAN2('Recovery Log'!P22,SQRT('Recovery Log'!Q22^2 + 'Recovery Log'!R22^2)))) -> n/a | AO22: =IF(AND(ISNUMBER(D22),ISNUMBER(E22)),(E22-D22)*24*60,"n/a") -> n/a | AP22: =IF(AND(ISNUMBER(G22),ISNUMBER(H22)),(H22-G22)*24*60,"n/a") -> n/a | AQ22: =IF(AND(ISNUMBER(G22),ISNUMBER('Recovery Log'!K22)),(G22-'Recovery Log'!K22)*24*60,"n/a") -> n/a | AR22: =IF(AND(ISNUMBER(H22),ISNUMBER(I22)),(I22-H22)*24*60,"n/a") -> n/a | AS22: =IF(AND(ISNUMBER('Recovery Log'!I22),ISNUMBER('Recovery Log'!N22)),('Recovery Log'!N22-'Recovery Log'!I22)*24*60,"n/a") -> n/a | AT22: =IF(ISNUMBER(AO22),O22/AO22,"n/a") -> n/a | AU22: =IF(ISNUMBER(AP22),O22/AP22,"n/a") -> n/a
A23: ='Deployment Log'!A23 -> 0 | B23: ='Deployment Log'!S23 -> 0 | C23: ='Deployment Log'!T23 -> 0 | D23: =IF('Deployment Log'!N23>DATE(2021,8,1),'Deployment Log'!N23,"n/a") -> n/a | E23: =IF('Deployment Log'!O23>DATE(2021,8,1),'Deployment Log'!O23,"n/a") -> n/a | F23: =IF('Deployment Log'!P23>DATE(2021,8,1),'Deployment Log'!P23,"n/a") -> n/a | G23: =IF('Recovery Log'!L23>DATE(2021,8,1),'Recovery Log'!L23,"n/a") -> n/a | H23: =IF('Recovery Log'!M23>DATE(2021,8,1),'Recovery Log'!M23,"n/a") -> n/a | I23: =IF(MIN('Recovery Log'!N23:O23)>DATE(2021,8,1),MIN('Recovery Log'!N23:O23),"n/a") -> n/a | J23: ='Deployment Log'!B23 -> 0 | K23: ='Deployment Log'!C23 -> 0 | L23: ='Deployment Log'!D23 -> 0 | M23: ='Deployment Log'!I23 -> 0 | N23: ='Deployment Log'!J23 -> 0 | O23: ='Deployment Log'!K23 -> 0 | P23: ='Deployment Log'!L23 | U23: =IF(ISBLANK(Q23),"",2*6370*ASIN(SQRT(SIN(RADIANS(Q23-M23)/2)*SIN(RADIANS(Q23-M23)/2) + COS(RADIANS(Q23))*COS(RADIANS(M23))*SIN(RADIANS(R23-N23)/2)*SIN(RADIANS(R23-N23)/2)))*1000) | V23: =ABS(U23/S23) -> #VALUE! | W23: =IF(ISBLANK(Q23),"",MOD(DEGREES(ATAN2(COS(RADIANS(M23))*SIN(RADIANS(Q23)) - SIN(RADIANS(M23))*COS(RADIANS(Q23))*COS(RADIANS(R23-N23)),COS(RADIANS(Q23))*SIN(RADIANS(R23-N23)))) + 360, 360)) | X23: =IF('Recovery Log'!V23="","",'Recovery Log'!V23) | Y23: =IF('Recovery Log'!W23="","",'Recovery Log'!W23) | AA23: =IF(ISBLANK(Q23),"",MOD(DEGREES(ATAN2(COS(RADIANS(Q23))*SIN(RADIANS(X23)) - SIN(RADIANS(Q23))*COS(RADIANS(X23))*COS(RADIANS(Y23-R23)),COS(RADIANS(X23))*SIN(RADIANS(Y23-R23)))) + 360, 360)) | AB23: =IF('Recovery Log'!Y23="","",'Recovery Log'!Y23) | AC23: =IF('Recovery Log'!Z23="","",'Recovery Log'!Z23) | AF23: =IF(ISBLANK(Q23),"",2*6370*ASIN(SQRT(SIN(RADIANS(Q23-J23)/2)*SIN(RADIANS(Q23-J23)/2) + COS(RADIANS(Q23))*COS(RADIANS(J23))*SIN(RADIANS(R23-K23)/2)*SIN(RADIANS(R23-K23)/2)))*1000) | AG23: =IF(ISBLANK(Q23),"",MOD(DEGREES(ATAN2(COS(RADIANS(J23))*SIN(RADIANS(Q23)) - SIN(RADIANS(J23))*COS(RADIANS(Q23))*COS(RADIANS(R23-K23)),COS(RADIANS(Q23))*SIN(RADIANS(R23-K23)))) + 360, 360)) | AH23: =IF('Recovery Log'!O23>'Deployment Log'!M23,'Recovery Log'!O23-'Deployment Log'!M23,"n/a") -> n/a | AI23: =IF(AND(ISNUMBER(G23),ISNUMBER(E23)),G23-E23,"n/a") -> n/a | AJ23: =IF(ISNUMBER(AH23),'Recovery Log'!AC23/AH23,"n/a") -> n/a | AK23: =IF(ISNUMBER(AJ23),1000000*AJ23/(24*60*60*1000),"n/a") -> n/a | AL23: =IF(ISNUMBER(AJ23),250+AJ23/24/60/60/250,"n/a") -> n/a | AM23: =IF(ISBLANK('Deployment Log'!AF23),"n/a",DEGREES(ATAN2('Deployment Log'!AF23,SQRT('Deployment Log'!AG23^2 + 'Deployment Log'!AH23^2)))) -> n/a | AN23: =IF(ISBLANK('Recovery Log'!P23),"n/a",DEGREES(ATAN2('Recovery Log'!P23,SQRT('Recovery Log'!Q23^2 + 'Recovery Log'!R23^2)))) -> n/a | AO23: =IF(AND(ISNUMBER(D23),ISNUMBER(E23)),(E23-D23)*24*60,"n/a") -> n/a | AP23: =IF(AND(ISNUMBER(G23),ISNUMBER(H23)),(H23-G23)*24*60,"n/a") -> n/a | AQ23: =IF(AND(ISNUMBER(G23),ISNUMBER('Recovery Log'!K23)),(G23-'Recovery Log'!K23)*24*60,"n/a") -> n/a | AR23: =IF(AND(ISNUMBER(H23),ISNUMBER(I23)),(I23-H23)*24*60,"n/a") -> n/a | AS23: =IF(AND(ISNUMBER('Recovery Log'!I23),ISNUMBER('Recovery Log'!N23)),('Recovery Log'!N23-'Recovery Log'!I23)*24*60,"n/a") -> n/a | AT23: =IF(ISNUMBER(AO23),O23/AO23,"n/a") -> n/a | AU23: =IF(ISNUMBER(AP23),O23/AP23,"n/a") -> n/a

Sheet Deployment Log
A1: Station Name | B1: Planned Location | I1: Actual Launch Location | M1: Date/Time (UTC) | S1: OBS | U1: Firmware Versions | W1: Acoustic Modem | Y1: Beacons | AB1: Battery SOC | AC1: Burn-wire Batch | AD1: Burn-wire Test Voltage | AF1: MEMS Accelerometer | AI1: Magnetometer | AL1: Technician(s) Responsible | AN1: Comments
B2: Latitude | C2: Longitude | D2: Depth (m) | E2: Latitude Degrees | F2: Latitude Minutes | G2: Longitude Degrees | H2: Longitude Minutes | I2: Latitude | J2: Longitude | K2: Depth (m) | L2: Distance from Planned (km) | M2: Recording Start | N2: Launch | O2: On Seafloor | P2: Survey Start | Q2: Survey End | R2: Programmed Release | S2: Name | T2: Serial | U2: Minimus | V2: Femtomus | W2: Address | X2: UID | Y2: Apollo S/N | Z2: VHF S/N | AA2: VHF frequency (MHz) | AB2: % | AD2: Widget | AE2: Dunker | AF2: Z | AG2: N | AH2: E | AI2: Z | AJ2: N | AK2: E | AL2: Programming | AM2: Survey
A3: Station | B3: Planned Latitude | C3: Planned Longitude | D3: Planned Depth (m) | E3: Latitude Degrees | F3: Latitude Minutes | G3: Longitude Degrees | H3: Longitude Minutes | I3: Launch Latitude | J3: Launch Longitude | K3: Water Depth at Launch (m) | L3: Distance Launch from Planned (km) | M3: Recording Start Date/Time (UTC) | N3: Launch Date/Time (UTC) | O3: Date/Time on Seafloor (UTC) | P3: Survey Start Date/Time (UTC) | Q3: Survey End Date/Time (UTC) | R3: Programmed Release Date/Time (UTC) | S3: OBS Name | T3: OBS ID | U3: Minimus Firmware | V3: Femtomus Firmware | W3: Acoustic Modem Address | X3: Acoustic Modem UID | Y3: Apollo S/N | Z3: XMB S/N | AA3: Radio beacon frequency (MHz) | AB3: Battery SOC at Deployment (%) | AC3: Burn-wire Batch | AD3: Burn-wire Widget Test Voltage | AE3: Burn-wire Dunker Test Voltage | AF3: AccZ | AG3: AccN | AH3: AccE | AI3: MagZ | AJ3: MagN | AK3: MagE | AL3: Programming Technician | AM3: Survey Technician | AN3: Deployment Comments
B4: =E4+F4/60 -> 0 | C4: =-(G4+H4/60) -> 0 | L4: =IF(OR(ISBLANK(B4),ISBLANK(I4)),"",2*6370*ASIN(SQRT(SIN(RADIANS(I4-B4)/2)*SIN(RADIANS(I4-B4)/2) + COS(RADIANS(I4))*COS(RADIANS(B4))*SIN(RADIANS(J4-C4)/2)*SIN(RADIANS(J4-C4)/2))))
B5: =E5+F5/60 -> 0 | C5: =-(G5+H5/60) -> 0 | L5: =IF(OR(ISBLANK(B5),ISBLANK(I5)),"",2*6370*ASIN(SQRT(SIN(RADIANS(I5-B5)/2)*SIN(RADIANS(I5-B5)/2) + COS(RADIANS(I5))*COS(RADIANS(B5))*SIN(RADIANS(J5-C5)/2)*SIN(RADIANS(J5-C5)/2))))
B6: =E6+F6/60 -> 0 | C6: =-(G6+H6/60) -> 0 | L6: =IF(OR(ISBLANK(B6),ISBLANK(I6)),"",2*6370*ASIN(SQRT(SIN(RADIANS(I6-B6)/2)*SIN(RADIANS(I6-B6)/2) + COS(RADIANS(I6))*COS(RADIANS(B6))*SIN(RADIANS(J6-C6)/2)*SIN(RADIANS(J6-C6)/2))))
B7: =E7+F7/60 -> 0 | C7: =-(G7+H7/60) -> 0 | L7: =IF(OR(ISBLANK(B7),ISBLANK(I7)),"",2*6370*ASIN(SQRT(SIN(RADIANS(I7-B7)/2)*SIN(RADIANS(I7-B7)/2) + COS(RADIANS(I7))*COS(RADIANS(B7))*SIN(RADIANS(J7-C7)/2)*SIN(RADIANS(J7-C7)/2))))
B8: =E8+F8/60 -> 0 | C8: =-(G8+H8/60) -> 0 | L8: =IF(OR(ISBLANK(B8),ISBLANK(I8)),"",2*6370*ASIN(SQRT(SIN(RADIANS(I8-B8)/2)*SIN(RADIANS(I8-B8)/2) + COS(RADIANS(I8))*COS(RADIANS(B8))*SIN(RADIANS(J8-C8)/2)*SIN(RADIANS(J8-C8)/2))))
B9: =E9+F9/60 -> 0 | C9: =-(G9+H9/60) -> 0 | L9: =IF(OR(ISBLANK(B9),ISBLANK(I9)),"",2*6370*ASIN(SQRT(SIN(RADIANS(I9-B9)/2)*SIN(RADIANS(I9-B9)/2) + COS(RADIANS(I9))*COS(RADIANS(B9))*SIN(RADIANS(J9-C9)/2)*SIN(RADIANS(J9-C9)/2))))
B10: =E10+F10/60 -> 0 | C10: =-(G10+H10/60) -> 0 | L10: =IF(OR(ISBLANK(B10),ISBLANK(I10)),"",2*6370*ASIN(SQRT(SIN(RADIANS(I10-B10)/2)*SIN(RADIANS(I10-B10)/2) + COS(RADIANS(I10))*COS(RADIANS(B10))*SIN(RADIANS(J10-C10)/2)*SIN(RADIANS(J10-C10)/2))))
B11: =E11+F11/60 -> 0 | C11: =-(G11+H11/60) -> 0 | L11: =IF(OR(ISBLANK(B11),ISBLANK(I11)),"",2*6370*ASIN(SQRT(SIN(RADIANS(I11-B11)/2)*SIN(RADIANS(I11-B11)/2) + COS(RADIANS(I11))*COS(RADIANS(B11))*SIN(RADIANS(J11-C11)/2)*SIN(RADIANS(J11-C11)/2))))
B12: =E12+F12/60 -> 0 | C12: =-(G12+H12/60) -> 0 | L12: =IF(OR(ISBLANK(B12),ISBLANK(I12)),"",2*6370*ASIN(SQRT(SIN(RADIANS(I12-B12)/2)*SIN(RADIANS(I12-B12)/2) + COS(RADIANS(I12))*COS(RADIANS(B12))*SIN(RADIANS(J12-C12)/2)*SIN(RADIANS(J12-C12)/2))))
B13: =E13+F13/60 -> 0 | C13: =-(G13+H13/60) -> 0 | L13: =IF(OR(ISBLANK(B13),ISBLANK(I13)),"",2*6370*ASIN(SQRT(SIN(RADIANS(I13-B13)/2)*SIN(RADIANS(I13-B13)/2) + COS(RADIANS(I13))*COS(RADIANS(B13))*SIN(RADIANS(J13-C13)/2)*SIN(RADIANS(J13-C13)/2))))
B14: =E14+F14/60 -> 0 | C14: =-(G14+H14/60) -> 0 | L14: =IF(OR(ISBLANK(B14),ISBLANK(I14)),"",2*6370*ASIN(SQRT(SIN(RADIANS(I14-B14)/2)*SIN(RADIANS(I14-B14)/2) + COS(RADIANS(I14))*COS(RADIANS(B14))*SIN(RADIANS(J14-C14)/2)*SIN(RADIANS(J14-C14)/2))))
B15: =E15+F15/60 -> 0 | C15: =-(G15+H15/60) -> 0 | L15: =IF(OR(ISBLANK(B15),ISBLANK(I15)),"",2*6370*ASIN(SQRT(SIN(RADIANS(I15-B15)/2)*SIN(RADIANS(I15-B15)/2) + COS(RADIANS(I15))*COS(RADIANS(B15))*SIN(RADIANS(J15-C15)/2)*SIN(RADIANS(J15-C15)/2))))
... B23: =E23+F23/60 -> 0 | C23: =-(G23+H23/60) -> 0 | L23: =IF(OR(ISBLANK(B23),ISBLANK(I23)),"",2*6370*ASIN(SQRT(SIN(RADIANS(I23-B23)/2)*SIN(RADIANS(I23-B23)/2) + COS(RADIANS(I23))*COS(RADIANS(B23))*SIN(RADIANS(J23-C23)/2)*SIN(RADIANS(J23-C23)/2))))

Sheet Recovery Log
A1: Station Name | B1: OBS Location as Deployed | E1: OBS | G1: Acoustic Modem | I1: Date/Time (UTC) | P1: MEMS Accelerometer | S1: Magnetometer | V1: First Surfacing | Y1: Recovery Location | AB1: Clock Offset (ms) | AD1: Battery SOC | AE1: Backup hard drive IDs | AF1: Technician(s) Responsible | AH1: Comments
B2: Latitude | C2: Longitude | D2: Depth (m) | E2: Name | F2: Serial | G2: Address | H2: UID | I2: On Station | J2: Acoustic contact | K2: Burn Command | L2: Released | M2: Surfacing | N2: On deck | O2: Recording stopped | P2: Z | Q2: N | R2: E | S2: Z | T2: N | U2: E | V2: Latitude | W2: Longitude | X2: Rise Drift (km) | Y2: Latitude | Z2: Longitude | AA2: Surface Drift (km) | AB2: Seafloor | AC2: On deck | AD2: % | AF2: Acoustics | AG2: On-Deck
A3: Station | B3: Deployed Latitude | C3: Deployed Longitude | D3: Water Depth (m) | E3: OBS Name | F3: OBS ID | G3: Acoustic Modem Address | H3: Acoustic Modem UID | I3: Date/Time on Station (UTC) | J3: Date/Time Acoustic Contact Established (UTC) | K3: Date/Time First Burn Command (UTC) | L3: Date/Time Released from Anchor (UTC) | M3: Surfacing Date/Time (UTC) | N3: On-Deck Date/Time (UTC) | O3: Date/Time Recording Stopped (UTC) | P3: AccZ | Q3: AccN | R3: AccE | S3: MagZ | T3: MagN | U3: MagE | V3: Surfacing Latitude | W3: Surfacing Longitude | X3: Horizontal Drift during Rise (km) | Y3: Recovery Latitude | Z3: Recovery Longitude | AA3: Drift on Surface (km) | AB3: Clock Offset at Seabed (ms) | AC3: Clock Offset on Deck (ms) | AD3: Battery SOC at Recovery (%) | AE3: Backup hard drive IDs | AF3: Acoustics Technician | AG3: Recovery Technician | AH3: Recovery Comments
A4: ='Deployment Log'!A4 -> 0 | B4: =Locations!Q4 -> 0 | C4: =Locations!R4 -> 0 | D4: =-Locations!S4 -> 0 | E4: =IF('Deployment Log'!S4="","",'Deployment Log'!S4) | F4: =IF('Deployment Log'!T4="","",'Deployment Log'!T4) | G4: =IF('Deployment Log'!W4="","",'Deployment Log'!W4) | H4: =IF('Deployment Log'!X4="","",'Deployment Log'!X4) | X4: =IF(ISBLANK(V4),"",2*6370*ASIN(SQRT(SIN(RADIANS(V4-B4)/2)*SIN(RADIANS(V4-B4)/2) + COS(RADIANS(V4))*COS(RADIANS(B4))*SIN(RADIANS(W4-C4)/2)*SIN(RADIANS(W4-C4)/2)))) | AA4: =IF(OR(ISBLANK(V4),ISBLANK(Y4)),"",2*6370*ASIN(SQRT(SIN(RADIANS(Y4-V4)/2)*SIN(RADIANS(Y4-V4)/2) + COS(RADIANS(Y4))*COS(RADIANS(V4))*SIN(RADIANS(Z4-W4)/2)*SIN(RADIANS(Z4-W4)/2))))
A5: ='Deployment Log'!A5 -> 0 | B5: =Locations!Q5 -> 0 | C5: =Locations!R5 -> 0 | D5: =-Locations!S5 -> 0 | E5: =IF('Deployment Log'!S5="","",'Deployment Log'!S5) | F5: =IF('Deployment Log'!T5="","",'Deployment Log'!T5) | G5: =IF('Deployment Log'!W5="","",'Deployment Log'!W5) | H5: =IF('Deployment Log'!X5="","",'Deployment Log'!X5) | X5: =IF(ISBLANK(V5),"",2*6370*ASIN(SQRT(SIN(RADIANS(V5-B5)/2)*SIN(RADIANS(V5-B5)/2) + COS(RADIANS(V5))*COS(RADIANS(B5))*SIN(RADIANS(W5-C5)/2)*SIN(RADIANS(W5-C5)/2)))) | AA5: =IF(OR(ISBLANK(V5),ISBLANK(Y5)),"",2*6370*ASIN(SQRT(SIN(RADIANS(Y5-V5)/2)*SIN(RADIANS(Y5-V5)/2) + COS(RADIANS(Y5))*COS(RADIANS(V5))*SIN(RADIANS(Z5-W5)/2)*SIN(RADIANS(Z5-W5)/2))))
A6: ='Deployment Log'!A6 -> 0 | B6: =Locations!Q6 -> 0 | C6: =Locations!R6 -> 0 | D6: =-Locations!S6 -> 0 | E6: =IF('Deployment Log'!S6="","",'Deployment Log'!S6) | F6: =IF('Deployment Log'!T6="","",'Deployment Log'!T6) | G6: =IF('Deployment Log'!W6="","",'Deployment Log'!W6) | H6: =IF('Deployment Log'!X6="","",'Deployment Log'!X6) | X6: =IF(ISBLANK(V6),"",2*6370*ASIN(SQRT(SIN(RADIANS(V6-B6)/2)*SIN(RADIANS(V6-B6)/2) + COS(RADIANS(V6))*COS(RADIANS(B6))*SIN(RADIANS(W6-C6)/2)*SIN(RADIANS(W6-C6)/2)))) | AA6: =IF(OR(ISBLANK(V6),ISBLANK(Y6)),"",2*6370*ASIN(SQRT(SIN(RADIANS(Y6-V6)/2)*SIN(RADIANS(Y6-V6)/2) + COS(RADIANS(Y6))*COS(RADIANS(V6))*SIN(RADIANS(Z6-W6)/2)*SIN(RADIANS(Z6-W6)/2))))
A7: ='Deployment Log'!A7 -> 0 | B7: =Locations!Q7 -> 0 | C7: =Locations!R7 -> 0 | D7: =-Locations!S7 -> 0 | E7: =IF('Deployment Log'!S7="","",'Deployment Log'!S7) | F7: =IF('Deployment Log'!T7="","",'Deployment Log'!T7) | G7: =IF('Deployment Log'!W7="","",'Deployment Log'!W7) | H7: =IF('Deployment Log'!X7="","",'Deployment Log'!X7) | X7: =IF(ISBLANK(V7),"",2*6370*ASIN(SQRT(SIN(RADIANS(V7-B7)/2)*SIN(RADIANS(V7-B7)/2) + COS(RADIANS(V7))*COS(RADIANS(B7))*SIN(RADIANS(W7-C7)/2)*SIN(RADIANS(W7-C7)/2)))) | AA7: =IF(OR(ISBLANK(V7),ISBLANK(Y7)),"",2*6370*ASIN(SQRT(SIN(RADIANS(Y7-V7)/2)*SIN(RADIANS(Y7-V7)/2) + COS(RADIANS(Y7))*COS(RADIANS(V7))*SIN(RADIANS(Z7-W7)/2)*SIN(RADIANS(Z7-W7)/2))))
A8: ='Deployment Log'!A8 -> 0 | B8: =Locations!Q8 -> 0 | C8: =Locations!R8 -> 0 | D8: =-Locations!S8 -> 0 | E8: =IF('Deployment Log'!S8="","",'Deployment Log'!S8) | F8: =IF('Deployment Log'!T8="","",'Deployment Log'!T8) | G8: =IF('Deployment Log'!W8="","",'Deployment Log'!W8) | H8: =IF('Deployment Log'!X8="","",'Deployment Log'!X8) | X8: =IF(ISBLANK(V8),"",2*6370*ASIN(SQRT(SIN(RADIANS(V8-B8)/2)*SIN(RADIANS(V8-B8)/2) + COS(RADIANS(V8))*COS(RADIANS(B8))*SIN(RADIANS(W8-C8)/2)*SIN(RADIANS(W8-C8)/2)))) | AA8: =IF(OR(ISBLANK(V8),ISBLANK(Y8)),"",2*6370*ASIN(SQRT(SIN(RADIANS(Y8-V8)/2)*SIN(RADIANS(Y8-V8)/2) + COS(RADIANS(Y8))*COS(RADIANS(V8))*SIN(RADIANS(Z8-W8)/2)*SIN(RADIANS(Z8-W8)/2))))
A9: ='Deployment Log'!A9 -> 0 | B9: =Locations!Q9 -> 0 | C9: =Locations!R9 -> 0 | D9: =-Locations!S9 -> 0 | E9: =IF('Deployment Log'!S9="","",'Deployment Log'!S9) | F9: =IF('Deployment Log'!T9="","",'Deployment Log'!T9) | G9: =IF('Deployment Log'!W9="","",'Deployment Log'!W9) | H9: =IF('Deployment Log'!X9="","",'Deployment Log'!X9) | X9: =IF(ISBLANK(V9),"",2*6370*ASIN(SQRT(SIN(RADIANS(V9-B9)/2)*SIN(RADIANS(V9-B9)/2) + COS(RADIANS(V9))*COS(RADIANS(B9))*SIN(RADIANS(W9-C9)/2)*SIN(RADIANS(W9-C9)/2)))) | AA9: =IF(OR(ISBLANK(V9),ISBLANK(Y9)),"",2*6370*ASIN(SQRT(SIN(RADIANS(Y9-V9)/2)*SIN(RADIANS(Y9-V9)/2) + COS(RADIANS(Y9))*COS(RADIANS(V9))*SIN(RADIANS(Z9-W9)/2)*SIN(RADIANS(Z9-W9)/2))))
A10: ='Deployment Log'!A10 -> 0 | B10: =Locations!Q10 -> 0 | C10: =Locations!R10 -> 0 | D10: =-Locations!S10 -> 0 | E10: =IF('Deployment Log'!S10="","",'Deployment Log'!S10) | F10: =IF('Deployment Log'!T10="","",'Deployment Log'!T10) | G10: =IF('Deployment Log'!W10="","",'Deployment Log'!W10) | H10: =IF('Deployment Log'!X10="","",'Deployment Log'!X10) | X10: =IF(ISBLANK(V10),"",2*6370*ASIN(SQRT(SIN(RADIANS(V10-B10)/2)*SIN(RADIANS(V10-B10)/2) + COS(RADIANS(V10))*COS(RADIANS(B10))*SIN(RADIANS(W10-C10)/2)*SIN(RADIANS(W10-C10)/2)))) | AA10: =IF(OR(ISBLANK(V10),ISBLANK(Y10)),"",2*6370*ASIN(SQRT(SIN(RADIANS(Y10-V10)/2)*SIN(RADIANS(Y10-V10)/2) + COS(RADIANS(Y10))*COS(RADIANS(V10))*SIN(RADIANS(Z10-W10)/2)*SIN(RADIANS(Z10-W10)/2))))
A11: ='Deployment Log'!A11 -> 0 | B11: =Locations!Q11 -> 0 | C11: =Locations!R11 -> 0 | D11: =-Locations!S11 -> 0 | E11: =IF('Deployment Log'!S11="","",'Deployment Log'!S11) | F11: =IF('Deployment Log'!T11="","",'Deployment Log'!T11) | G11: =IF('Deployment Log'!W11="","",'Deployment Log'!W11) | H11: =IF('Deployment Log'!X11="","",'Deployment Log'!X11) | X11: =IF(ISBLANK(V11),"",2*6370*ASIN(SQRT(SIN(RADIANS(V11-B11)/2)*SIN(RADIANS(V11-B11)/2) + COS(RADIANS(V11))*COS(RADIANS(B11))*SIN(RADIANS(W11-C11)/2)*SIN(RADIANS(W11-C11)/2)))) | AA11: =IF(OR(ISBLANK(V11),ISBLANK(Y11)),"",2*6370*ASIN(SQRT(SIN(RADIANS(Y11-V11)/2)*SIN(RADIANS(Y11-V11)/2) + COS(RADIANS(Y11))*COS(RADIANS(V11))*SIN(RADIANS(Z11-W11)/2)*SIN(RADIANS(Z11-W11)/2))))
